Workbook
Name _GoBack: Constiuence!#REF!

Sheet Booth detail
A1: erns; LFky la0 | B1: 1 | C1: 2 | D1: 3 | E1: 4 | F1: 5 | G1: 6 | H1: 7 | I1: 8 | J1: 9 | K1: 10 | L1: 11 | M1: 12 | N1: 13 | O1: 14 | P1: 15 | Q1: 16 | R1: 17 | S1: 18 | T1: 19 | U1: 20 | V1: 21 | W1: 22 | X1: 23 | Y1: 24 | Z1: 25 | AA1: 26 | AB1: 27 | AC1: 28 | AD1: 29 | AE1: 30 | AF1: 31 | AG1: 32 | AH1: 33 | AI1: 34 | AJ1: 35 | AK1: 36 | AL1: 37 | AM1: 38 | AN1: 39 | AO1: 40 | AP1: 41 | AQ1: 42 | AR1: 43 | AS1: 44 | AT1: 45 | AU1: 46 | AV1: 47 | AW1: 48 | AX1: 49 | AY1: 50 | AZ1: 51 | BA1: 52 | BB1: 53 | BC1: 54 | BD1: 55 | BE1: 56 | BF1: 57 | BG1: 58 | BH1: 59 | BI1: 60 | BJ1: 61 | BK1: 62 | BL1: 63 | BM1: 64 | BN1: 65 | BO1: 66 | BP1: 67 | BQ1: 68 | BR1: 69 | BS1: 70 | BT1: 71 | BU1: 72 | BV1: 73 | BW1: 74 | BX1: 75 | BY1: 76 | BZ1: 77 | CA1: 78 | CB1: 79 | CC1: 80 | CD1: 81 | CE1: 82 | CF1: 83 | CG1: 84 | CH1: 85 | CI1: 86 | CJ1: 87 | CK1: 88 | CL1: 89 | CM1: 90 | CN1: 91 | CO1: 92 | CP1: 93 | CQ1: 94 | CR1: 95 | CS1: 96 | CT1: 97 | CU1: 98 | CV1: 99 | CW1: 100 | CX1: 101 | CY1: 102 | CZ1: 103 | DA1: 104 | DB1: 105 | DC1: 106 | DD1: 107 | DE1: 108 | DF1: 109 | DG1: 110 | DH1: 111 | DI1: 112 | DJ1: 113 | DK1: 114 | DL1: 115 | DM1: 116 | DN1: 117 | DO1: 118 | DP1: 119 | DQ1: 120 | DR1: 121 | DS1: 122 | DT1: 123 | DU1: 124 | DV1: 125 | DW1: 126 | DX1: 127 | DY1: 128 | DZ1: 129 | EA1: 130 | EB1: 131 | EC1: 132 | ED1: 133 | EE1: 134 | EF1: 135 | EG1: 136 | EH1: 137 | EI1: 138 | EJ1: 139 | EK1: 140 | EL1: 141 | EM1: 142 | EN1: 143 | EO1: 144 | EP1: 145 | EQ1: 146 | ER1: 147 | ES1: 148 | ET1: 149 | EU1: 150 | EV1: 151 | EW1: 152 | EX1: 153 | EY1: 154 | EZ1: 155 | FA1: 156 | FB1: 157 | FC1: 158 | FD1: 159 | FE1: 160 | FF1: 161 | FG1: 162 | FH1: 163 | FI1: 164 | FJ1: 165 | FK1: 166 | FL1: 167 | FM1: 168 | FN1: 169 | FO1: 170 | FP1: 171 | FQ1: 172 | FR1: 173 | FS1: 174 | FT1: 175 | FU1: 176 | FV1: 177 | FW1: 178 | FX1: 179 | FY1: 180 | FZ1: 181 | GA1: 182 | GB1: 183 | GC1: 184 | GD1: 185 | GE1: 186 | GF1: 187 | GG1: 188 | GH1: 189 | GI1: 190 | GJ1: 191 | GK1: 192 | GL1: 193 | GM1: 194 | GN1: 195 | GO1: 196 | GP1: 197 | GQ1: 198 | GR1: 199 | GS1: 200 | GT1: 201 | GU1: 202 | GV1: 203 | GW1: 204 | GX1: 205 | GY1: 206 | GZ1: 207 | HA1: 208 | HB1: 209 | HC1: 210 | HD1: 211 | HE1: 212 | HF1: 213 | HG1: 214 | HH1: 215 | HI1: 216 | HJ1: 217 | HK1: 218 | HL1: 219 | HM1: 220 | HN1: 221 | HO1: 222 | HP1: 223 | HQ1: 224 | HR1: 225 | HS1: 226 | HT1: 227 | HU1: 228 | HV1: 229 | HW1: 230 | HX1: 231 | HY1: 232 | HZ1: 233 | IA1: 234 | IB1: 235 | IC1: 236 | ID1: 237 | IE1: 238 | IF1: 239 | IG1: 240 | IH1: 241 | II1: 242 | IJ1: 243 | IK1: 244 | IL1: 245 | IM1: 246 | IN1: 247 | IO1: 248 | IP1: 249 | IQ1: 250 | IR1: 251 | IS1: 252 | IT1: 253 | IU1: 254 | IV1: 255 | IW1: 256 | IX1: 257 | IY1: 258 | IZ1: 259 | JA1: 260 | JB1: 261 | JC1: 262 | JD1: 263 | JE1: 264 | JF1: 265 | JG1: 266 | JH1: 267 | JI1: 268 | JJ1: 269 | JK1: 270 | JL1: 271 | JM1: 272 | JN1: 273 | JO1: 274 | JP1: 275 | JQ1: 276 | JR1: 277 | JS1: 278 | JT1: 279 | JU1: 280 | JV1: 281 | JW1: 282 | JX1: 283 | JY1: 284 | JZ1: 285 | KA1: 286 | KB1: 287 | KC1: 288 | KD1: 289 | KE1: 290 | KF1: 291 | KG1: 292 | KH1: 293 | KI1: 294 | KJ1: 295 | KK1: 296 | KL1: 297 | KM1: 298 | KN1: 299 | KO1: 300 | KP1: 301 | KQ1: 302 | KR1: 303 | KS1: 304 | KT1: 305 | KU1: 306 | KV1: 307 | KW1: 308 | KX1: 309 | KY1: 310 | KZ1: 311 | LA1: 312 | LB1: 313 | LC1: 314 | LD1: 315 | LE1: 316 | LF1: 317 | LG1: 318 | LH1: 319 | LI1: 320 | LJ1: 321 | LK1: 322 | LL1: 323 | LM1: 324 | LN1: 325 | LO1: 326 | LP1: 327 | LQ1: 328 | LR1: 329 | LS1: 330 | LT1: 331 | LU1: 332 | LV1: 333 | LW1: 334 | LX1: 335 | LY1: 336 | LZ1: 337 | MA1: 338 | MB1: 339 | MC1: 340 | MD1: 341 | ME1: 342 | MF1: 343 | MG1: 344 | MH1: 345 | MI1: 346 | MJ1: 347 | MK1: 348 | ML1: 349 | MM1: 350 | MN1: 351 | MO1: 352 | MP1: 353 | MQ1: 354 | MR1: 355 | MS1: 356 | MT1: 357 | MU1: 358 | MV1: 359 | MW1: 360 | MX1: 361 | MY1: 362 | MZ1: 363 | NA1: 364 | NB1: 365 | NC1: 366 | ND1: 367 | NE1: 368 | NF1: 369 | NG1: 370 | NH1: 371 | NI1: 372 | NJ1: 373 | NK1: 374 | NL1: 375 | NM1: 376 | NN1: 377 | NO1: 378 | NP1: 379 | NQ1: 380 | NR1: 381 | NS1: 382 | NT1: 383 | NU1: 384 | NV1: 385 | NW1: 386 | NX1: 387 | NY1: 388 | NZ1: 389 | OA1: 390 | OB1: 391 | OC1: 392 | OD1: 393 | OE1: 394 | OF1: 395 | OG1: 396 | OH1: 397 | OI1: 398 | OJ1: 399 | OK1: 400 | OL1: 401 | OM1: 402 | ON1: 403 | OO1: 404 | OP1: 405 | OQ1: 406 | OR1: 407 | OS1: 408 | OT1: 409 | OU1: 410 | OV1: 411 | OW1: 412 | OX1: 413 | OY1: 414 | OZ1: 415 | PA1: 416 | PB1: 417 | PC1: 418 | PD1: 419 | PE1: 420 | PF1: 421 | PG1: 422 | PH1: 423 | PI1: 424 | PJ1: 425 | PK1: 426 | PL1: 427 | PM1: 428 | PN1: 429 | PO1: 430 | PP1: 431 | PQ1: 432 | PR1: 433 | PS1: 434 | PT1: 435 | PU1: 436 | PV1: 437 | PW1: 438 | PX1: 439 | PY1: 440 | PZ1: 441 | QA1: 442 | QB1: 443 | QC1: 444 | QD1: 445 | QE1: 446 | QF1: 447 | QG1: 448 | QH1: 449 | QI1: 450 | QJ1: 451 | QK1: 452 | QL1: 453 | QM1: 454 | QN1: 455 | QO1: 456 | QP1: 457 | QQ1: 458 | QR1: 459 | QS1: 460 | QT1: 461 | QU1: 462 | QV1: 463 | QW1: 464 | QX1: 465 | QY1: 466 | QZ1: 467 | RA1: 468 | RB1: 469 | RC1: 470 | RD1: 471 | RE1: 472
A2: daVªksy ;wfuV dk dzekad | B2: ECUEC64547 | C2: ECUEC57499 | D2: ECUEC53812 | E2: ECUEC50315 | F2: ECUEC29676 | G2: ECUEC57702 | H2: ECUEC64518 | I2: ECUEC64882 | J2: ECUEC51429 | K2: ECUEC64809 | L2: ECUEC54951 | M2: ECUEC57760 | N2: ECUEC47766 | O2: ECUEC50174 | P2: ECUED29544 | Q2: ECUEC64240 | R2: ECUEC52847 | S2: ECUEC57886 | T2: ECUEC51183 | U2: ECUEC64330 | V2: ECUEC57577 | W2: ECUEC64629 | X2: ECUEC64669 | Y2: ECUEC67556 | Z2: ECUEC51902 | AA2: ECUEC64790 | AB2: ECUEC60441 | AC2: ECUEC67625 | AD2: ECUEC64718 | AE2: ECUEC57643 | AF2: ECUEC57935 | AG2: ECUEC67180 | AH2: ECUEC57289 | AI2: ECUEC54284 | AJ2: ECUED21486 | AK2: ECUEC67774 | AL2: ECUEC48866 | AM2: ECUEC51355 | AN2: ECUEC57759 | AO2: ECUEC64570 | AP2: ECUEC51140 | AQ2: ECUEC57058 | AR2: ECUEC57429 | AS2: ECUEC64461 | AT2: ECUEC64242 | AU2: ECUEC57867 | AV2: ECUEC47938 | AW2: ECUEC53960 | AX2: ECUEC51884 | AY2: ECUEC50064 | AZ2: ECUEC57178 | BA2: ECUED14258 | BB2: ECUEC98388 | BC2: ECUED21809 | BD2: ECUEC57567 | BE2: ECUEC57297 | BF2: ECUEC50673 | BG2: ECUEC99007 | BH2: ECUEC55794 | BI2: ECUEC64839 | BJ2: ECUEC50624 | BK2: ECUEC60741 | BL2: ECUEC48655 | BM2: ECUEC54259 | BN2: ECUEC64961 | BO2: ECUEC64716 | BP2: ECUED22273 | BQ2: ECUEC64702 | BR2: ECUEC50237 | BS2: ECUEC67331 | BT2: ECUEC64355 | BU2: ECUEC50447 | BV2: ECUED23454 | BW2: ECUEC57225 | BX2: ECUEC64757 | BY2: ECUEC63789 | BZ2: ECUEC67408 | CA2: ECUED29149 | CB2: ECUEC51904 | CC2: ECUEC60105 | CD2: ECUEC57485 / ECUEC63670 | CE2: ECUEC52549 | CF2: ECUEC67909 | CG2: ECUEC64732 | CH2: ECUEC64252 | CI2: ECUEC67125 | CJ2: ECUEC57795 | CK2: ECUEC47827 | CL2: ECUEC50087 | CM2: ECUEC67504 | CN2: ECUEC60070 | CO2: ECUEC57938 | CP2: ECUEC57505 | CQ2: ECUEC64592 | CR2: ECUEC64624 | CS2: ECUEC67463 | CT2: ECUEC50246 | CU2: ECUEC64335 | CV2: ECUEC50800 | CW2: ECUEC64174 | CX2: ECUEC64625 | CY2: ECUEC54532 | CZ2: ECUEC51602 | DA2: ECUEC64742 | DB2: ECUEC64386 | DC2: ECUEC50223 | DD2: ECUEC64230 | DE2: ECUEC57883 | DF2: ECUED12254 | DG2: ECUEC51702 | DH2: ECUEC50429 | DI2: ECUEC64957 | DJ2: ECUEC57163 | DK2: ECUEC67502 | DL2: ECUEC63888 | DM2: ECUED02101 | DN2: ECUEC67456 | DO2: ECUED24138 | DP2: ECUEC57426 | DQ2: ECUEC57993 | DR2: ECUEC52991 | DS2: ECUEC63859 | DT2: ECUEC67668 | DU2: ECUEC67678 | DV2: ECUEC50170 | DW2: ECUEC54579 | DX2: ECUEC52431 | DY2: ECUEC57502 | DZ2: ECUEC51550 | EA2: ECUEC57698 | EB2: ECUEC60514 | EC2: ECUED21253 | ED2: ECUEC60524 | EE2: ECUEC67407 | EF2: ECUEC60062 | EG2: ECUEC57652 | EH2: ECUED25812 | EI2: ECUEC47988 | EJ2: ECUEC57590 | EK2: ECUED23799 | EL2: ECUEC47912 | EM2: ECUEC50598 | EN2: ECUEC57424 | EO2: ECUEC57739 | EP2: ECUEC64634 | EQ2: ECUEC64357 | ER2: ECUEC64070 | ES2: ECUEC50122 | ET2: ECUEC53760 | EU2: ECUEC57820 | EV2: ECUED21469 | EW2: ECUEC54571 | EX2: ECUEC50155 | EY2: ECUEC63814 | EZ2: ECUEC54366 | FA2: ECUEC57675 | FB2: ECUEC50225 | FC2: ECUEC47949 | FD2: ECUED11571 | FE2: ECUEC60410 | FF2: ECUEC50691 | FG2: ECUEC50481 | FH2: ECUED21424 | FI2: ECUEC51559 | FJ2: ECUEC57450 | FK2: ECUEC59989 | FL2: ECUEC64692 | FM2: ECUEC59952 | FN2: ECUEC63064 | FO2: ECUEC67759 | FP2: ECUED14045 | FQ2: ECUED24195 | FR2: ECUEC50541 | FS2: ECUEC57578 | FT2: ECUEC57839 | FU2: ECUEC60568 | FV2: ECUEC64566 | FW2: ECUEC57483 | FX2: ECUEC64546 | FY2: ECUEC55334 | FZ2: ECUEC53874 | GA2: ECUEC47914 | GB2: ECUEC60157 | GC2: ECUEC52363 | GD2: ECUEC63596 | GE2: ECUEC51278 | GF2: ECUEC53730 | GG2: ECUEC57895 | GH2: ECUEC54526 | GI2: ECUEC64759 | GJ2: ECUEC57438 | GK2: ECUEC54425 | GL2: ECUEC48582 | GM2: ECUEC47873 | GN2: ECUEC64236 | GO2: ECUEC50613 | GP2: ECUEC54414 | GQ2: ECUEC55593 | GR2: ECUEC54765 | GS2: ECUEC57525 | GT2: ECUEC47872 | GU2: ECUEC48978 | GV2: ECUEC97810 | GW2: ECUEC57932 | GX2: ECUEC47418 | GY2: ECUEC51128 | GZ2: ECUEC67748 | HA2: ECUEC64854 | HB2: ECUED12136 | HC2: ECUEC57944 | HD2: ECUEC51620 | HE2: ECUED12152 | HF2: ECUEC67949 | HG2: ECUEC64903 | HH2: ECUEC60614 | HI2: ECUED25753 | HJ2: ECUEC64632 | HK2: ECUEC60494 | HL2: ECUEC50422 | HM2: ECUEC64964 | HN2: ECUEC67799 | HO2: ECUEC51379 | HP2: ECUEC64980 | HQ2: ECUEC48878 | HR2: ECUEC64930 | HS2: ECUEC57696 | HT2: ECUEC50396 | HU2: ECUED24545 | HV2: ECUEC98811 | HW2: ECUEC55905 | HX2: ECUED23064 | HY2: ECUEC67998 | HZ2: ECUEC60802 | IA2: ECUEC64474 | IB2: ECUEC67794 | IC2: ECUEC67480 | ID2: ECUED23861 | IE2: ECUED24516 | IF2: ECUEC64921 | IG2: ECUEC55735 | IH2: ECUEC51209 | II2: ECUED11340 | IJ2: ECUEC57677 | IK2: ECUEC64359 | IL2: ECUEC65059 | IM2: ECUEC47740 | IN2: ECUEC52588 | IO2: ECUEC50220 | IP2: ECUEC57713 | IQ2: ECUEC57831 | IR2: ECUED00162 | IS2: ECUEC50811 | IT2: ECUEC50097 | IU2: ECUED29579 | IV2: ECUEC67721 | IW2: ECUEC67421 | IX2: ECUEC60721 | IY2: ECUEC57492 | IZ2: ECUEC51172 | JA2: ECUEC57477 | JB2: ECUED29317 | JC2: ECUEC67413 | JD2: ECUEC54603 | JE2: ECUEC50943 | JF2: ECUEC64682 | JG2: ECUEC64193 | JH2: ECUEC47732 | JI2: ECUEC64545 | JJ2: ECUEC60295 | JK2: ECUEC50450 | JL2: ECUEC63782 | JM2: ECUEC60520 | JN2: ECUEC60347 | JO2: ECUEC53986 | JP2: ECUED29239 | JQ2: ECUEC47909 | JR2: ECUED29891 | JS2: ECUED21446 | JT2: ECUEC57122 | JU2: ECUEC47962 | JV2: ECUEC51319 | JW2: ECUEC51268 | JX2: ECUED23812 | JY2: ECUEC51177 | JZ2: ECUED29285 | KA2: ECUEC51296 | KB2: ECUEC67335 | KC2: ECUEC50126 | KD2: ECUEC52620 | KE2: ECUEC50745 | KF2: ECUEC50178 | KG2: ECUEC67981 | KH2: ECUEC48796 | KI2: ECUEC57308 | KJ2: ECUEC67959 | KK2: ECUEC52485 | KL2: ECUEC57980 | KM2: ECUEC57741 | KN2: ECUEC67245 | KO2: ECUEC53767 | KP2: ECUEC64418 | KQ2: ECUEC63590 | KR2: ECUEC60594 | KS2: ECUEC47807 | KT2: ECUEC52759 | KU2: ECUEC53030 | KV2: ECUEC57548 | KW2: ECUEC67570 | KX2: ECUED23406 | KY2: ECUEC50389 | KZ2: ECUED29938 | LA2: ECUEC67080 | LB2: ECUEC57948 | LC2: ECUEC60219 | LD2: ECUEC59978 | LE2: ECUEC57229 | LF2: ECUEC67321 | LG2: ECUEC67420 | LH2: ECUEC67662 | LI2: ECUED21857 | LJ2: ECUEC63674 | LK2: ECUEC48411 | LL2: ECUEC57211 | LM2: ECUEC50095 | LN2: ECUEC67425 | LO2: ECUED25095 | LP2: ECUED14315 | LQ2: ECUEC54024 | LR2: ECUED12259 | LS2: ECUEC57415 | LT2: ECUEC50653 | LU2: ECUEC64929 | LV2: ECUEC50532 | LW2: ECUEC67617 | LX2: ECUEC50648 | LY2: ECUEC51527 | LZ2: ECUED14247 | MA2: ECUED24989 | MB2: ECUEC47893 | MC2: ECUEC57922 | MD2: ECUEC67343 | ME2: ECUEC57766 | MF2: ECUEC64373 | MG2: ECUEC47955 | MH2: ECUEC63179 | MI2: ECUEC50102 | MJ2: ECUEC64794 | MK2: ECUEC67535 | ML2: ECUEC63678 | MM2: ECUEC60935 | MN2: ECUEC98675 | MO2: ECUED25020 | MP2: ECUEC54150 | MQ2: ECUEC64710 | MR2: ECUEC64688 | MS2: ECUED25211 | MT2: ECUEC57227 | MU2: ECUEC67560 | MV2: ECUED22276 | MW2: ECUEC64130 | MX2: ECUEC64605 | MY2: ECUEC55762 | MZ2: ECUEC64148 | NA2: ECUEC67055 | NB2: ECUEC57563 | NC2: ECUEC52102 | ND2: ECUEC63623 | NE2: ECUEC67765 | NF2: ECUEC50403 | NG2: ECUEC53743 | NH2: ECUEC64939 | NI2: ECUEC64382 | NJ2: ECUEC50604 | NK2: ECUED25639 | NL2: ECUED29128 | NM2: ECUEC51505 | NN2: ECUEC67087/ ECUED11300 | NO2: ECUEC64835 | NP2: ECUED07082 | NQ2: ECUEC57218 | NR2: ECUEC50427 | NS2: ECUED24881 | NT2: ECUED23652 | NU2: ECUEC64920 | NV2: ECUEC67567 | NW2: ECUEC52557 | NX2: ECUEC51064 | NY2: ECUEC60119 | NZ2: ECUEC57873 | OA2: ECUED25082 | OB2: ECUEC64714 | OC2: ECUEC64982 | OD2: ECUEC64918 | OE2: ECUEC60670 | OF2: ECUEC54129 | OG2: ECUEC53920 | OH2: ECUEC67991 | OI2: ECUED24951 | OJ2: ECUED22341 | OK2: ECUEC57188 | OL2: ECUEC64975 | OM2: ECUEC57890 | ON2: ECUEC50995 | OO2: ECUEC64841 | OP2: ECUEC64959 | OQ2: ECUEC67605 | OR2: ECUEC54320 | OS2: ECUEC57854 | OT2: ECUEC47765 | OU2: ECUEC54084 | OV2: ECUEC51365 | OW2: ECUEC67677 | OX2: ECUEC60730 | OY2: ECUEC57726 | OZ2: ECUED24121 | PA2: ECUEC50066 | PB2: ECUEC50830 | PC2: ECUEC51470 | PD2: ECUEC57513 | PE2: ECUEC98442 | PF2: ECUEC60554 | PG2: ECUEC57861 | PH2: ECUEC60579/ ECUEC50182 | PI2: ECUEC57413 | PJ2: ECUEC60978 | PK2: ECUEC64211 | PL2: ECUEC57673 | PM2: ECUEC51828 | PN2: ECUED15456 | PO2: ECUED00327 | PP2: ECUEC64621 | PQ2: ECUED24977 | PR2: ECUEC64559 | PS2: ECUEC50731 | PT2: ECUEC55092 | PU2: ECUEC67615 | PV2: ECUEC60321 | PW2: ECUEC51926 | PX2: ECUEC60411 | PY2: ECUED29348 | PZ2: ECUEC51109 | QA2: ECUEC51218 | QB2: ECUEC64764 | QC2: ECUEC47826 | QD2: ECUEC60232 | QE2: ECUEC64363 | QF2: ECUEC60434 | QG2: ECUED21381 | QH2: ECUEC47889 | QI2: ECUEC50338 | QJ2: ECUEC62436 | QK2: ECUED23646 | QL2: ECUEC57796 | QM2: ECUED21633 | QN2: ECUEC47381 | QO2: ECUEC57549 | QP2: ECUED24410 | QQ2: ECUEC50997 | QR2: ECUEC51091 | QS2: ECUEC64901 | QT2: ECUED25149 | QU2: ECUEC57961 | QV2: ECUEC50136 | QW2: ECUEC52283 | QX2: ECUEC60250 | QY2: ECUEC52333 | QZ2: ECUEC57779 | RA2: ECUEC54014 | RB2: ECUEC57638 | RC2: ECUEC50559 | RD2: ECUEC57405 | RE2: ECUEC67305
A3: dqy iMs er | B3: - | C3: - | D3: - | E3: - | F3: - | G3: - | H3: - | I3: - | J3: - | K3: - | L3: - | M3: - | N3: - | O3: - | P3: - | Q3: - | R3: - | S3: - | T3: - | U3: - | V3: - | W3: - | X3: - | Y3: - | Z3: - | AA3: - | AB3: - | AC3: - | AD3: - | AE3: - | AF3: - | AG3: - | AH3: - | AI3: - | AJ3: - | AK3: - | AL3: - | AM3: - | AN3: - | AO3: - | AP3: - | AQ3: - | AR3: - | AS3: - | AT3: - | AU3: - | AV3: - | AW3: - | AX3: - | AY3: - | AZ3: - | BA3: - | BB3: - | BC3: - | BD3: - | BE3: - | BF3: - | BG3: - | BH3: - | BI3: - | BJ3: - | BK3: - | BL3: - | BM3: - | BN3: - | BO3: - | BP3: - | BQ3: - | BR3: - | BS3: - | BT3: - | BU3: - | BV3: - | BW3: - | BX3: - | BY3: - | BZ3: - | CA3: - | CB3: - | CC3: - | CD3: - | CE3: - | CF3: - | CG3: - | CH3: - | CI3: - | CJ3: - | CK3: - | CL3: - | CM3: - | CN3: - | CO3: - | CP3: - | CQ3: - | CR3: - | CS3: - | CT3: - | CU3: - | CV3: - | CW3: - | CX3: - | CY3: - | CZ3: - | DA3: - | DB3: - | DC3: - | DD3: - | DE3: - | DF3: - | DG3: - | DH3: - | DI3: - | DJ3: - | DK3: - | DL3: - | DM3: - | DN3: - | DO3: - | DP3: - | DQ3: - | DR3: - | DS3: - | DT3: - | DU3: - | DV3: - | DW3: - | DX3: - | DY3: - | DZ3: - | EA3: - | EB3: - | EC3: - | ED3: - | EE3: - | EF3: - | EG3: - | EH3: - | EI3: - | EJ3: - | EK3: - | EL3: - | EM3: - | EN3: - | EO3: - | EP3: - | EQ3: - | ER3: - | ES3: - | ET3: - | EU3: - | EV3: - | EW3: - | EX3: - | EY3: - | EZ3: - | FA3: - | FB3: - | FC3: - | FD3: - | FE3: - | FF3: - | FG3: - | FH3: - | FI3: - | FJ3: - | FK3: - | FL3: - | FM3: - | FN3: - | FO3: - | FP3: - | FQ3: - | FR3: - | FS3: - | FT3: - | FU3: - | FV3: - | FW3: - | FX3: - | FY3: - | FZ3: - | GA3: - | GB3: - | GC3: - | GD3: - | GE3: - | GF3: - | GG3: - | GH3: - | GI3: - | GJ3: - | GK3: - | GL3: - | GM3: - | GN3: - | GO3: - | GP3: - | GQ3: - | GR3: - | GS3: - | GT3: - | GU3: - | GV3: - | GW3: - | GX3: - | GY3: - | GZ3: - | HA3: - | HB3: - | HC3: - | HD3: - | HE3: - | HF3: - | HG3: - | HH3: - | HI3: - | HJ3: - | HK3: - | HL3: - | HM3: - | HN3: - | HO3: - | HP3: - | HQ3: - | HR3: - | HS3: - | HT3: - | HU3: - | HV3: - | HW3: - | HX3: - | HY3: - | HZ3: - | IA3: - | IB3: - | IC3: - | ID3: - | IE3: - | IF3: - | IG3: - | IH3: - | II3: - | IJ3: - | IK3: - | IL3: - | IM3: - | IN3: - | IO3: - | IP3: - | IQ3: - | IR3: - | IS3: - | IT3: - | IU3: - | IV3: - | IW3: - | IX3: - | IY3: - | IZ3: - | JA3: - | JB3: - | JC3: - | JD3: - | JE3: - | JF3: - | JG3: - | JH3: - | JI3: - | JJ3: - | JK3: - | JL3: - | JM3: - | JN3: - | JO3: - | JP3: - | JQ3: - | JR3: - | JS3: - | JT3: - | JU3: - | JV3: - | JW3: - | JX3: - | JY3: - | JZ3: - | KA3: - | KB3: - | KC3: - | KD3: - | KE3: - | KF3: - | KG3: - | KH3: - | KI3: - | KJ3: - | KK3: - | KL3: - | KM3: - | KN3: - | KO3: - | KP3: - | KQ3: - | KR3: - | KS3: - | KT3: - | KU3: - | KV3: - | KW3: - | KX3: - | KY3: - | KZ3: - | LA3: - | LB3: - | LC3: - | LD3: - | LE3: - | LF3: - | LG3: - | LH3: - | LI3: - | LJ3: - | LK3: - | LL3: - | LM3: - | LN3: - | LO3: - | LP3: - | LQ3: - | LR3: - | LS3: - | LT3: - | LU3: - | LV3: - | LW3: - | LX3: - | LY3: - | LZ3: - | MA3: - | MB3: - | MC3: - | MD3: - | ME3: - | MF3: - | MG3: - | MH3: - | MI3: - | MJ3: - | MK3: - | ML3: - | MM3: - | MN3: - | MO3: - | MP3: - | MQ3: - | MR3: - | MS3: - | MT3: - | MU3: - | MV3: - | MW3: - | MX3: - | MY3: - | MZ3: - | NA3: - | NB3: - | NC3: - | ND3: - | NE3: - | NF3: - | NG3: - | NH3: - | NI3: - | NJ3: - | NK3: - | NL3: - | NM3: - | NN3: - | NO3: - | NP3: - | NQ3: - | NR3: - | NS3: - | NT3: - | NU3: - | NV3: - | NW3: - | NX3: - | NY3: - | NZ3: - | OA3: - | OB3: - | OC3: - | OD3: - | OE3: - | OF3: - | OG3: - | OH3: - | OI3: - | OJ3: - | OK3: - | OL3: - | OM3: - | ON3: - | OO3: - | OP3: - | OQ3: - | OR3: - | OS3: - | OT3: - | OU3: - | OV3: - | OW3: - | OX3: - | OY3: - | OZ3: - | PA3: - | PB3: - | PC3: - | PD3: - | PE3: - | PF3: - | PG3: - | PH3: - | PI3: - | PJ3: - | PK3: - | PL3: - | PM3: - | PN3: - | PO3: - | PP3: - | PQ3: - | PR3: - | PS3: - | PT3: - | PU3: - | PV3: - | PW3: - | PX3: - | PY3: - | PZ3: - | QA3: - | QB3: - | QC3: - | QD3: - | QE3: - | QF3: - | QG3: - | QH3: - | QI3: - | QJ3: - | QK3: - | QL3: - | QM3: - | QN3: - | QO3: - | QP3: - | QQ3: - | QR3: - | QS3: - | QT3: - | QU3: - | QV3: - | QW3: - | QX3: - | QY3: - | QZ3: - | RA3: - | RB3: - | RC3: - | RD3: - | RE3: -

Sheet Candidate List
A1: SI | B1: Name of Candidate
A2: 1 | B2: Manveer Singh
A3: 2 | B3: Rahul Yadav
A4: 3 | B4: Lakshmi Raj
A5: 4 | B5: Saleem Akhtar Khan
A6: 5 | B6: Ajay Kumar
A7: 6 | B7: Ajay Kumar Sharma
A8: 7 | B8: Amit Singh Tomar
A9: 8 | B9: Darshan Sharma
A10: 9 | B10: Dilshad Ahmad
A11: 10 | B11: Raju Thakur
A12: 11 | B12: Bablu
A13: 12 | B13: NOTA

Sheet Constiuence
A1: Annexure for tabulating round-wise figures (Refer Para 27)
A2: Number & Name of Constituency - 64-Sikandrabad | K2: Round No.1 | P2: Date | R2: 44630
A3: Table No. | C3: 1 | D3: 2 | E3: 3 | F3: 4 | G3: 5 | H3: 6 | I3: 7 | J3: 8 | K3: 9 | L3: 10 | M3: 11 | N3: 12 | O3: 13 | P3: 14 | Q3: Total | R3: Brought from Previous Round | S3: Cummulative Total
A4: Polling Booth No. | C4: ='Booth detail'!B1 -> 1 | D4: ='Booth detail'!C1 -> 2 | E4: ='Booth detail'!D1 -> 3 | F4: ='Booth detail'!E1 -> 4 | G4: ='Booth detail'!F1 -> 5 | H4: ='Booth detail'!G1 -> 6 | I4: ='Booth detail'!H1 -> 7 | J4: ='Booth detail'!I1 -> 8 | ... P4: ='Booth detail'!O1 -> 14
A5: Control Unit No. | C5: ='Booth detail'!B2 -> ECUEC64547 | D5: ='Booth detail'!C2 -> ECUEC57499 | E5: ='Booth detail'!D2 -> ECUEC53812 | F5: ='Booth detail'!E2 -> ECUEC50315 | G5: ='Booth detail'!F2 -> ECUEC29676 | H5: ='Booth detail'!G2 -> ECUEC57702 | I5: ='Booth detail'!H2 -> ECUEC64518 | J5: ='Booth detail'!I2 -> ECUEC64882 | ... P5: ='Booth detail'!O2 -> ECUEC50174
A6: Number of Electors assigned to the polling Station | C6: ='Booth detail'!B3 -> - | D6: ='Booth detail'!C3 -> - | E6: ='Booth detail'!D3 -> - | F6: ='Booth detail'!E3 -> - | G6: ='Booth detail'!F3 -> - | H6: ='Booth detail'!G3 -> - | I6: ='Booth detail'!H3 -> - | J6: ='Booth detail'!I3 -> - | ... P6: ='Booth detail'!O3 -> -
A7: SI | B7: Name of Candidate | C7: - | D7: - | E7: - | F7: - | G7: - | H7: - | I7: - | J7: - | K7: - | L7: - | M7: - | N7: - | O7: - | P7: -
A8: ='Candidate List'!A2 -> 1 | B8: ='Candidate List'!B2 -> Manveer Singh | C8: 2 | D8: 48 | E8: 89 | F8: 94 | G8: 31 | H8: 30 | I8: 115 | J8: 38 | K8: 12 | L8: 65 | M8: 151 | N8: 29 | O8: 16 | P8: 40 | Q8: =SUM(C8:P8) -> 760 | R8: 0 | S8: =Q8+R8 -> 760
A9: ='Candidate List'!A3 -> 2 | B9: ='Candidate List'!B3 -> Rahul Yadav | C9: 599 | D9: 440 | E9: 15 | F9: 275 | G9: 306 | H9: 7 | I9: 16 | J9: 45 | K9: 46 | L9: 85 | M9: 48 | N9: 79 | O9: 110 | P9: 103 | Q9: =SUM(C9:P9) -> 2174 | R9: 0 | S9: =Q9+R9 -> 2174
A10: ='Candidate List'!A4 -> 3 | B10: ='Candidate List'!B4 -> Lakshmi Raj | C10: 18 | D10: 42 | E10: 161 | F10: 34 | G10: 43 | H10: 342 | I10: 226 | J10: 254 | K10: 385 | L10: 210 | M10: 197 | N10: 282 | O10: 421 | P10: 282 | Q10: =SUM(C10:P10) -> 2897 | R10: 0 | S10: =Q10+R10 -> 2897
A11: ='Candidate List'!A5 -> 4 | B11: ='Candidate List'!B5 -> Saleem Akhtar Khan | C11: 3 | D11: 3 | E11: 1 | F11: 3 | G11: 3 | H11: 5 | I11: 3 | J11: 5 | K11: 2 | L11: 4 | M11: 3 | N11: 3 | O11: 0 | P11: 8 | Q11: =SUM(C11:P11) -> 46 | R11: 0 | S11: =Q11+R11 -> 46
A12: ='Candidate List'!A6 -> 5 | B12: ='Candidate List'!B6 -> Ajay Kumar | C12: 0 | D12: 1 | E12: 0 | F12: 2 | G12: 0 | H12: 7 | I12: 1 | J12: 2 | K12: 1 | L12: 1 | M12: 1 | N12: 1 | O12: 0 | P12: 12 | Q12: =SUM(C12:P12) -> 29 | R12: 0 | S12: =Q12+R12 -> 29
A13: ='Candidate List'!A7 -> 6 | B13: ='Candidate List'!B7 -> Ajay Kumar Sharma | C13: 0 | D13: 0 | E13: 0 | F13: 1 | G13: 0 | H13: 1 | I13: 2 | J13: 0 | K13: 0 | L13: 0 | M13: 0 | N13: 0 | O13: 0 | P13: 1 | Q13: =SUM(C13:P13) -> 5 | R13: 0 | S13: =Q13+R13 -> 5
A14: ='Candidate List'!A8 -> 7 | B14: ='Candidate List'!B8 -> Amit Singh Tomar | C14: 0 | D14: 1 | E14: 0 | F14: 1 | G14: 1 | H14: 1 | I14: 0 | J14: 0 | K14: 0 | L14: 0 | M14: 0 | N14: 0 | O14: 1 | P14: 0 | Q14: =SUM(C14:P14) -> 5 | R14: 0 | S14: =Q14+R14 -> 5
A15: ='Candidate List'!A9 -> 8 | B15: ='Candidate List'!B9 -> Darshan Sharma | C15: 0 | D15: 1 | E15: 0 | F15: 0 | G15: 2 | H15: 1 | I15: 5 | J15: 1 | K15: 1 | L15: 0 | M15: 0 | N15: 0 | O15: 1 | P15: 0 | Q15: =SUM(C15:P15) -> 12 | R15: 0 | S15: =Q15+R15 -> 12
A16: ='Candidate List'!A10 -> 9 | B16: ='Candidate List'!B10 -> Dilshad Ahmad | C16: 6 | D16: 5 | E16: 0 | F16: 56 | G16: 48 | H16: 0 | I16: 1 | J16: 0 | K16: 0 | L16: 2 | M16: 0 | N16: 0 | O16: 0 | P16: 0 | Q16: =SUM(C16:P16) -> 118 | R16: 0 | S16: =Q16+R16 -> 118
A17: ='Candidate List'!A11 -> 10 | B17: ='Candidate List'!B11 -> Raju Thakur | C17: 2 | D17: 2 | E17: 2 | F17: 5 | G17: 2 | H17: 2 | I17: 2 | J17: 1 | K17: 3 | L17: 1 | M17: 1 | N17: 3 | O17: 2 | P17: 2 | Q17: =SUM(C17:P17) -> 30 | R17: 0 | S17: =Q17+R17 -> 30
A18: ='Candidate List'!A12 -> 11 | B18: ='Candidate List'!B12 -> Bablu | C18: 0 | D18: 3 | E18: 0 | F18: 0 | G18: 1 | H18: 1 | I18: 1 | J18: 1 | K18: 2 | L18: 0 | M18: 0 | N18: 1 | O18: 1 | P18: 0 | Q18: =SUM(C18:P18) -> 11 | R18: 0 | S18: =Q18+R18 -> 11
A19: ='Candidate List'!A13 -> 12 | B19: ='Candidate List'!B13 -> NOTA | C19: 2 | D19: 1 | E19: 0 | F19: 3 | G19: 4 | H19: 2 | I19: 0 | J19: 8 | K19: 1 | L19: 0 | M19: 4 | N19: 0 | O19: 1 | P19: 1 | Q19: =SUM(C19:P19) -> 27 | R19: 0 | S19: =Q19+R19 -> 27
A20: Rejected Votes | C20: 0 | D20: 0 | E20: 0 | F20: 0 | G20: 0 | H20: 0 | I20: 0 | J20: 0 | K20: 0 | L20: 0 | M20: 0 | N20: 0 | O20: 0 | P20: 0 | Q20: =SUM(C20:P20) -> 0 | R20: 0 | S20: =Q20+R20 -> 0
A21: Total Votes | C21: =SUM(C8:C20) -> 632 | D21: =SUM(D8:D20) -> 547 | E21: =SUM(E8:E20) -> 268 | F21: =SUM(F8:F20) -> 474 | G21: =SUM(G8:G20) -> 441 | H21: =SUM(H8:H20) -> 399 | I21: =SUM(I8:I20) -> 372 | J21: =SUM(J8:J20) -> 355 | ... P21: =SUM(P8:P20) -> 449 | Q21: =SUM(C21:P21) -> 6114 | R21: 0 | S21: =Q21+R21 -> 6114
C23: Initial of RO | D23: Initial of RO | E23: Initial of RO | F23: Initial of RO | G23: Initial of RO | H23: Initial of RO | I23: Initial of RO | J23: Initial of RO | K23: Initial of RO | L23: Initial of RO | M23: Initial of RO | N23: Initial of RO | O23: Initial of RO | P23: Initial of RO | Q23: Initial of RO | R23: Initial of RO | S23: Initial of RO
C25: Initial of observer | D25: Initial of observer | E25: Initial of observer | F25: Initial of observer | G25: Initial of observer | H25: Initial of observer | I25: Initial of observer | J25: Initial of observer | K25: Initial of observer | L25: Initial of observer | M25: Initial of observer | N25: Initial of observer | O25: Initial of observer | P25: Initial of observer | Q25: Initial of observer | R25: Initial of observer | S25: Initial of observer
A27: Important :- | C27: 1. All overwritings/cuttings should be certified by observer.
C28: 2. Polling station number whose votes are counted should be indicated below the table number.
C29: 3. The EVM (CU) no. used in the polling station will be specifically verified and tick marked by the form Part II of 17C
C30: 4. A copy of this is to be kept by observer in a separate folder for cross checking later.
A33: Annexure for tabulating round-wise figures (Refer Para 27)
A34: Number & Name of Constituency - 64-Sikandrabad | K34: Round No.2 | P34: Date | R34: 44630
A35: Table No. | C35: 1 | D35: 2 | E35: 3 | F35: 4 | G35: 5 | H35: 6 | I35: 7 | J35: 8 | K35: 9 | L35: 10 | M35: 11 | N35: 12 | O35: 13 | P35: 14 | Q35: Total | R35: Brought from Previous Round | S35: Cummulative Total
A36: Polling Booth No. | C36: ='Booth detail'!P1 -> 15 | D36: ='Booth detail'!Q1 -> 16 | E36: ='Booth detail'!R1 -> 17 | F36: ='Booth detail'!S1 -> 18 | G36: ='Booth detail'!T1 -> 19 | H36: ='Booth detail'!U1 -> 20 | I36: ='Booth detail'!V1 -> 21 | J36: ='Booth detail'!W1 -> 22 | ... P36: ='Booth detail'!AC1 -> 28
A37: Control Unit No. | C37: ='Booth detail'!P2 -> ECUED29544 | D37: ='Booth detail'!Q2 -> ECUEC64240 | E37: ='Booth detail'!R2 -> ECUEC52847 | F37: ='Booth detail'!S2 -> ECUEC57886 | G37: ='Booth detail'!T2 -> ECUEC51183 | H37: ='Booth detail'!U2 -> ECUEC64330 | I37: ='Booth detail'!V2 -> ECUEC57577 | J37: ='Booth detail'!W2 -> ECUEC64629 | ... P37: ='Booth detail'!AC2 -> ECUEC67625
A38: Number of Electors assigned to the polling Station | C38: ='Booth detail'!P3 -> - | D38: ='Booth detail'!Q3 -> - | E38: ='Booth detail'!R3 -> - | F38: ='Booth detail'!S3 -> - | G38: ='Booth detail'!T3 -> - | H38: ='Booth detail'!U3 -> - | I38: ='Booth detail'!V3 -> - | J38: ='Booth detail'!W3 -> - | ... P38: ='Booth detail'!AC3 -> -
A39: SI | B39: Name of Candidate | C39: - | D39: - | E39: - | F39: - | G39: - | H39: - | I39: - | J39: - | K39: - | L39: - | M39: - | N39: - | O39: - | P39: -
A40: 1 | B40: ='Candidate List'!B2 -> Manveer Singh | C40: 120 | D40: 81 | E40: 1 | F40: 3 | G40: 113 | H40: 4 | I40: 29 | J40: 255 | K40: 58 | L40: 134 | M40: 3 | N40: 303 | O40: 12 | P40: 16 | Q40: =SUM(C40:P40) -> 1132 | R40: =S8 -> 760 | S40: =Q40+R40 -> 1892
A41: 2 | B41: ='Candidate List'!B3 -> Rahul Yadav | C41: 241 | D41: 200 | E41: 380 | F41: 470 | G41: 212 | H41: 96 | I41: 258 | J41: 120 | K41: 29 | L41: 182 | M41: 384 | N41: 100 | O41: 122 | P41: 105 | Q41: =SUM(C41:P41) -> 2899 | R41: =S9 -> 2174 | S41: =Q41+R41 -> 5073
A42: 3 | B42: ='Candidate List'!B4 -> Lakshmi Raj | C42: 84 | D42: 55 | E42: 45 | F42: 8 | G42: 75 | H42: 398 | I42: 262 | J42: 210 | K42: 336 | L42: 150 | M42: 37 | N42: 147 | O42: 326 | P42: 514 | Q42: =SUM(C42:P42) -> 2647 | R42: =S10 -> 2897 | S42: =Q42+R42 -> 5544
A43: 4 | B43: ='Candidate List'!B5 -> Saleem Akhtar Khan | C43: 4 | D43: 1 | E43: 37 | F43: 31 | G43: 13 | H43: 5 | I43: 6 | J43: 1 | K43: 3 | L43: 10 | M43: 9 | N43: 1 | O43: 3 | P43: 8 | Q43: =SUM(C43:P43) -> 132 | R43: =S11 -> 46 | S43: =Q43+R43 -> 178
A44: 5 | B44: ='Candidate List'!B6 -> Ajay Kumar | C44: 1 | D44: 0 | E44: 1 | F44: 0 | G44: 1 | H44: 0 | I44: 0 | J44: 0 | K44: 0 | L44: 1 | M44: 0 | N44: 1 | O44: 0 | P44: 0 | Q44: =SUM(C44:P44) -> 5 | R44: =S12 -> 29 | S44: =Q44+R44 -> 34
A45: 6 | B45: ='Candidate List'!B7 -> Ajay Kumar Sharma | C45: 0 | D45: 0 | E45: 0 | F45: 0 | G45: 0 | H45: 0 | I45: 0 | J45: 0 | K45: 1 | L45: 0 | M45: 0 | N45: 0 | O45: 0 | P45: 0 | Q45: =SUM(C45:P45) -> 1 | R45: =S13 -> 5 | S45: =Q45+R45 -> 6
...

Sheet Total Round
A1: izk:Ik & 20
A2: vfUre ifj.kke&Ik=
A3: fu;e 56 lh ¼2½ lh
A4: fo/kku lHkk fuokZpu {ks= dk lkekU; fuokZpu&2022
A5: Hkkx&1
A6: fo/kku lHkk [k.M dk uke &64 fldUnjkckn | H6: fo/kkulHkk fuokZpu {ks= esa dqy ernkrkvksa dh la[;k- 397807
A7: dz0la0 | B7: jkm.M la[;k | C7: euohj flag | D7: jkgqy ;kno | E7: y{eh jkt | F7: lyhe v[krj [kka | G7: vt; dqekj | H7: vt; dqekj 'kekZZ | I7: vfer flag rksej | J7: n'kZu 'kekZ | K7: fny'kkn vgen | L7: jktw Bkdqj | M7: ccyw | N7: oS/k erksa dh dqy la[;k | O7: (Rejected) izfr{ksfir erksa dh la[;k | P7: uksVk fodYi ds fy;s er | Q7: dqy ;ksx | R7: ¼VsaMj½ fufonRr erksa dh la[;k
C8: 1 | D8: 2 | E8: 3 | F8: 4 | G8: 5 | H8: 6 | I8: 7 | J8: 8 | K8: 9 | L8: 10 | M8: 11
A9: 1 | B9: Round-1 | C9: =Constiuence!Q8 -> 760 | D9: =Constiuence!Q9 -> 2174 | E9: =Constiuence!Q10 -> 2897 | F9: =Constiuence!Q11 -> 46 | G9: =Constiuence!Q12 -> 29 | H9: =Constiuence!Q13 -> 5 | I9: =Constiuence!Q14 -> 5 | J9: =Constiuence!Q15 -> 12 | K9: =Constiuence!Q16 -> 118 | L9: =Constiuence!Q17 -> 30 | M9: =Constiuence!Q18 -> 11 | N9: =SUM(C9:M9) -> 6087 | O9: 0 | P9: 27 | Q9: =N9+P9+O9 -> 6114 | R9: 0
A10: 2 | B10: Round-2 | C10: =Constiuence!Q40 -> 1132 | D10: =Constiuence!Q41 -> 2899 | E10: =Constiuence!Q42 -> 2647 | F10: =Constiuence!Q43 -> 132 | G10: =Constiuence!Q44 -> 5 | H10: =Constiuence!Q45 -> 1 | I10: =Constiuence!Q46 -> 5 | J10: =Constiuence!Q47 -> 10 | K10: =Constiuence!Q48 -> 38 | L10: =Constiuence!Q49 -> 28 | M10: =Constiuence!Q50 -> 12 | N10: =SUM(C10:M10) -> 6909 | O10: 0 | P10: 30 | Q10: =N10+P10+O10 -> 6939 | R10: 0
A11: 3 | B11: Round-3 | C11: =Constiuence!Q73 -> 839 | D11: =Constiuence!Q74 -> 4233 | E11: =Constiuence!Q75 -> 3224 | F11: =Constiuence!Q76 -> 222 | G11: =Constiuence!Q77 -> 14 | H11: =Constiuence!Q78 -> 1 | I11: =Constiuence!Q79 -> 10 | J11: =Constiuence!Q80 -> 16 | K11: =Constiuence!Q81 -> 106 | L11: =Constiuence!Q82 -> 45 | M11: =Constiuence!Q83 -> 18 | N11: =SUM(C11:M11) -> 8728 | O11: 0 | P11: 39 | Q11: =N11+P11+O11 -> 8767 | R11: 0
A12: 4 | B12: Round-4 | C12: =Constiuence!Q106 -> 394 | D12: =Constiuence!Q107 -> 4538 | E12: =Constiuence!Q108 -> 1605 | F12: =Constiuence!Q109 -> 34 | G12: =Constiuence!Q110 -> 4 | H12: =Constiuence!Q111 -> 0 | I12: =Constiuence!Q112 -> 0 | J12: =Constiuence!Q113 -> 7 | K12: =Constiuence!Q114 -> 44 | L12: =Constiuence!Q115 -> 27 | M12: =Constiuence!Q116 -> 9 | N12: =SUM(C12:M12) -> 6662 | O12: 0 | P12: 19 | Q12: =N12+P12+O12 -> 6681 | R12: 0
A13: 5 | B13: Round-5 | C13: =Constiuence!Q139 -> 151 | D13: =Constiuence!Q140 -> 4149 | E13: =Constiuence!Q141 -> 3664 | F13: =Constiuence!Q142 -> 34 | G13: =Constiuence!Q143 -> 6 | H13: =Constiuence!Q144 -> 1 | I13: =Constiuence!Q145 -> 4 | J13: =Constiuence!Q146 -> 6 | K13: =Constiuence!Q147 -> 43 | L13: =Constiuence!Q148 -> 23 | M13: =Constiuence!Q149 -> 24 | N13: =SUM(C13:M13) -> 8105 | O13: 0 | P13: 35 | Q13: =N13+P13+O13 -> 8140 | R13: 0
A14: 6 | B14: Round-6 | C14: =Constiuence!Q172 -> 927 | D14: =Constiuence!Q173 -> 2804 | E14: =Constiuence!Q174 -> 3846 | F14: =Constiuence!Q175 -> 62 | G14: =Constiuence!Q176 -> 3 | H14: =Constiuence!Q177 -> 5 | I14: =Constiuence!Q178 -> 8 | J14: =Constiuence!Q179 -> 10 | K14: =Constiuence!Q180 -> 94 | L14: =Constiuence!Q181 -> 33 | M14: =Constiuence!Q182 -> 10 | N14: =SUM(C14:M14) -> 7802 | O14: 0 | P14: 28 | Q14: =N14+P14+O14 -> 7830 | R14: 0
A15: 7 | B15: Round-7 | C15: =Constiuence!Q205 -> 548 | D15: =Constiuence!Q206 -> 5012 | E15: =Constiuence!Q207 -> 1744 | F15: =Constiuence!Q208 -> 86 | G15: =Constiuence!Q209 -> 4 | H15: =Constiuence!Q210 -> 6 | I15: =Constiuence!Q211 -> 6 | J15: =Constiuence!Q212 -> 5 | K15: =Constiuence!Q213 -> 140 | L15: =Constiuence!Q214 -> 41 | M15: =Constiuence!Q215 -> 16 | N15: =SUM(C15:M15) -> 7608 | O15: 0 | P15: 27 | Q15: =N15+P15+O15 -> 7635 | R15: 0
A16: 8 | B16: Round-8 | C16: =Constiuence!Q238 -> 319 | D16: =Constiuence!Q239 -> 5469 | E16: =Constiuence!Q240 -> 1346 | F16: =Constiuence!Q241 -> 44 | G16: =Constiuence!Q242 -> 3 | H16: =Constiuence!Q243 -> 1 | I16: =Constiuence!Q244 -> 4 | J16: =Constiuence!Q245 -> 5 | K16: =Constiuence!Q246 -> 148 | L16: =Constiuence!Q247 -> 33 | M16: =Constiuence!Q248 -> 22 | N16: =SUM(C16:M16) -> 7394 | O16: 0 | P16: 24 | Q16: =N16+P16+O16 -> 7418 | R16: 0
A17: 9 | B17: Round-9 | C17: =Constiuence!Q271 -> 934 | D17: =Constiuence!Q272 -> 3328 | E17: =Constiuence!Q273 -> 3174 | F17: =Constiuence!Q274 -> 19 | G17: =Constiuence!Q275 -> 18 | H17: =Constiuence!Q276 -> 1 | I17: =Constiuence!Q277 -> 3 | J17: =Constiuence!Q278 -> 12 | K17: =Constiuence!Q279 -> 10 | L17: =Constiuence!Q280 -> 22 | M17: =Constiuence!Q281 -> 17 | N17: =SUM(C17:M17) -> 7538 | O17: 0 | P17: 38 | Q17: =N17+P17+O17 -> 7576 | R17: 0
A18: 10 | B18: Round-10 | C18: =Constiuence!Q306 -> 1730 | D18: =Constiuence!Q307 -> 2200 | E18: =Constiuence!Q308 -> 2654 | F18: =Constiuence!Q309 -> 28 | G18: =Constiuence!Q310 -> 29 | H18: =Constiuence!Q311 -> 5 | I18: =Constiuence!Q312 -> 6 | J18: =Constiuence!Q313 -> 9 | K18: =Constiuence!Q314 -> 9 | L18: =Constiuence!Q315 -> 25 | M18: =Constiuence!Q316 -> 10 | N18: =SUM(C18:M18) -> 6705 | O18: 0 | P18: 33 | Q18: =N18+P18+O18 -> 6738 | R18: 0
A19: 11 | B19: Round-11 | C19: =Constiuence!Q340 -> 1021 | D19: =Constiuence!Q341 -> 3663 | E19: =Constiuence!Q342 -> 3308 | F19: =Constiuence!Q343 -> 39 | G19: =Constiuence!Q344 -> 10 | H19: =Constiuence!Q345 -> 1 | I19: =Constiuence!Q346 -> 1 | J19: =Constiuence!Q347 -> 8 | K19: =Constiuence!Q348 -> 48 | L19: =Constiuence!Q349 -> 61 | M19: =Constiuence!Q350 -> 14 | N19: =SUM(C19:M19) -> 8174 | O19: 0 | P19: 30 | Q19: =N19+P19+O19 -> 8204 | R19: 0
A20: 12 | B20: Round-12 | C20: =Constiuence!Q375 -> 928 | D20: =Constiuence!Q376 -> 3637 | E20: =Constiuence!Q377 -> 2854 | F20: =Constiuence!Q378 -> 51 | G20: =Constiuence!Q379 -> 8 | H20: =Constiuence!Q380 -> 3 | I20: =Constiuence!Q381 -> 5 | J20: =Constiuence!Q382 -> 9 | K20: =Constiuence!Q383 -> 19 | L20: =Constiuence!Q384 -> 27 | M20: =Constiuence!Q385 -> 24 | N20: =SUM(C20:M20) -> 7565 | O20: 0 | P20: 34 | Q20: =N20+P20+O20 -> 7599 | R20: 0
A21: 13 | B21: Round-13 | C21: =Constiuence!Q409 -> 1133 | D21: =Constiuence!Q410 -> 2229 | E21: =Constiuence!Q411 -> 4536 | F21: =Constiuence!Q412 -> 67 | G21: =Constiuence!Q413 -> 8 | H21: =Constiuence!Q414 -> 5 | I21: =Constiuence!Q415 -> 7 | J21: =Constiuence!Q416 -> 21 | K21: =Constiuence!Q417 -> 21 | L21: =Constiuence!Q418 -> 41 | M21: =Constiuence!Q419 -> 15 | N21: =SUM(C21:M21) -> 8083 | O21: 0 | P21: 24 | Q21: =N21+P21+O21 -> 8107 | R21: 0
A22: 14 | B22: Round-14 | C22: =Constiuence!Q442 -> 3488 | D22: =Constiuence!Q443 -> 2765 | E22: =Constiuence!Q444 -> 2057 | F22: =Constiuence!Q445 -> 121 | G22: =Constiuence!Q446 -> 31 | H22: =Constiuence!Q447 -> 1 | I22: =Constiuence!Q448 -> 4 | J22: =Constiuence!Q449 -> 9 | K22: =Constiuence!Q450 -> 31 | L22: =Constiuence!Q451 -> 26 | M22: =Constiuence!Q452 -> 13 | N22: =SUM(C22:M22) -> 8546 | O22: 0 | P22: 63 | Q22: =N22+P22+O22 -> 8609 | R22: 0
A23: 15 | B23: Round-15 | C23: =Constiuence!Q477 -> 1689 | D23: =Constiuence!Q478 -> 2788 | E23: =Constiuence!Q479 -> 2991 | F23: =Constiuence!Q480 -> 43 | G23: =Constiuence!Q481 -> 55 | H23: =Constiuence!Q482 -> 3 | I23: =Constiuence!Q483 -> 9 | J23: =Constiuence!Q484 -> 12 | K23: =Constiuence!Q485 -> 36 | L23: =Constiuence!Q486 -> 47 | M23: =Constiuence!Q487 -> 10 | N23: =SUM(C23:M23) -> 7683 | O23: 0 | P23: 37 | Q23: =N23+P23+O23 -> 7720 | R23: 0
A24: 16 | B24: Round-16 | C24: =Constiuence!Q511 -> 3150 | D24: =Constiuence!Q512 -> 815 | E24: =Constiuence!Q513 -> 3853 | F24: =Constiuence!Q514 -> 53 | G24: =Constiuence!Q515 -> 250 | H24: =Constiuence!Q516 -> 6 | I24: =Constiuence!Q517 -> 13 | J24: =Constiuence!Q518 -> 26 | K24: =Constiuence!Q519 -> 19 | L24: =Constiuence!Q520 -> 33 | M24: =Constiuence!Q521 -> 17 | N24: =SUM(C24:M24) -> 8235 | O24: 0 | P24: 49 | Q24: =N24+P24+O24 -> 8284 | R24: 0
A25: 17 | B25: Round-17 | C25: =Constiuence!Q545 -> 1853 | D25: =Constiuence!Q546 -> 2047 | E25: =Constiuence!Q547 -> 5229 | F25: =Constiuence!Q548 -> 78 | G25: =Constiuence!Q549 -> 34 | H25: =Constiuence!Q550 -> 3 | I25: =Constiuence!Q551 -> 4 | J25: =Constiuence!Q552 -> 18 | K25: =Constiuence!Q553 -> 54 | L25: =Constiuence!Q554 -> 49 | M25: =Constiuence!Q555 -> 13 | N25: =SUM(C25:M25) -> 9382 | O25: 0 | P25: 48 | Q25: =N25+P25+O25 -> 9430 | R25: 0
A26: 18 | B26: Round-18 | C26: =Constiuence!Q579 -> 359 | D26: =Constiuence!Q580 -> 5625 | E26: =Constiuence!Q581 -> 3131 | F26: =Constiuence!Q582 -> 76 | G26: =Constiuence!Q583 -> 3 | H26: =Constiuence!Q584 -> 3 | I26: =Constiuence!Q585 -> 5 | J26: =Constiuence!Q586 -> 3 | K26: =Constiuence!Q587 -> 157 | L26: =Constiuence!Q588 -> 54 | M26: =Constiuence!Q589 -> 17 | N26: =SUM(C26:M26) -> 9433 | O26: 0 | P26: 24 | Q26: =N26+P26+O26 -> 9457 | R26: 0
A27: 19 | B27: Round-19 | C27: =Constiuence!Q613 -> 292 | D27: =Constiuence!Q614 -> 4283 | E27: =Constiuence!Q615 -> 3474 | F27: =Constiuence!Q616 -> 45 | G27: =Constiuence!Q617 -> 4 | H27: =Constiuence!Q618 -> 6 | I27: =Constiuence!Q619 -> 5 | J27: =Constiuence!Q620 -> 5 | K27: =Constiuence!Q621 -> 56 | L27: =Constiuence!Q622 -> 47 | M27: =Constiuence!Q623 -> 11 | N27: =SUM(C27:M27) -> 8228 | O27: 0 | P27: 17 | Q27: =N27+P27+O27 -> 8245 | R27: 0
A28: 20 | B28: Round-20 | C28: =Constiuence!Q646 -> 1711 | D28: =Constiuence!Q647 -> 1677 | E28: =Constiuence!Q648 -> 3995 | F28: =Constiuence!Q649 -> 59 | G28: =Constiuence!Q650 -> 11 | H28: =Constiuence!Q651 -> 2 | I28: =Constiuence!Q652 -> 6 | J28: =Constiuence!Q653 -> 8 | K28: =Constiuence!Q654 -> 56 | L28: =Constiuence!Q655 -> 34 | M28: =Constiuence!Q656 -> 15 | N28: =SUM(C28:M28) -> 7574 | O28: 0 | P28: 37 | Q28: =N28+P28+O28 -> 7611 | R28: 0
A29: 21 | B29: Round-21 | C29: =Constiuence!Q680 -> 756 | D29: =Constiuence!Q681 -> 3574 | E29: =Constiuence!Q682 -> 4115 | F29: =Constiuence!Q683 -> 78 | G29: =Constiuence!Q684 -> 11 | H29: =Constiuence!Q685 -> 4 | I29: =Constiuence!Q686 -> 9 | J29: =Constiuence!Q687 -> 10 | K29: =Constiuence!Q688 -> 82 | L29: =Constiuence!Q689 -> 39 | M29: =Constiuence!Q690 -> 7 | N29: =SUM(C29:M29) -> 8685 | O29: 0 | P29: 30 | Q29: =N29+P29+O29 -> 8715 | R29: 0
A30: 22 | B30: Round-22 | C30: =Constiuence!Q714 -> 1177 | D30: =Constiuence!Q715 -> 4338 | E30: =Constiuence!Q716 -> 1938 | F30: =Constiuence!Q717 -> 106 | G30: =Constiuence!Q718 -> 11 | H30: =Constiuence!Q719 -> 5 | I30: =Constiuence!Q720 -> 3 | J30: 13 | K30: =Constiuence!Q722 -> 96 | L30: =Constiuence!Q723 -> 25 | M30: =Constiuence!Q724 -> 12 | N30: =SUM(C30:M30) -> 7724 | O30: 0 | P30: 34 | Q30: =N30+P30+O30 -> 7758 | R30: 0
A31: 23 | B31: Round-23 | C31: =Constiuence!Q748 -> 969 | D31: =Constiuence!Q749 -> 1325 | E31: =Constiuence!Q750 -> 5543 | F31: =Constiuence!Q751 -> 80 | G31: =Constiuence!Q752 -> 15 | H31: =Constiuence!Q753 -> 3 | I31: =Constiuence!Q754 -> 7 | J31: =Constiuence!Q755 -> 14 | K31: =Constiuence!Q756 -> 35 | L31: =Constiuence!Q757 -> 44 | M31: =Constiuence!Q758 -> 18 | N31: =SUM(C31:M31) -> 8053 | O31: 0 | P31: 47 | Q31: =N31+P31+O31 -> 8100 | R31: 0
A32: 24 | B32: Round-24 | C32: =Constiuence!Q782 -> 2097 | D32: =Constiuence!Q783 -> 1279 | E32: =Constiuence!Q784 -> 3714 | F32: =Constiuence!Q785 -> 36 | G32: =Constiuence!Q786 -> 43 | H32: =Constiuence!Q787 -> 6 | I32: =Constiuence!Q788 -> 3 | J32: =Constiuence!Q789 -> 13 | K32: =Constiuence!Q790 -> 10 | L32: =Constiuence!Q791 -> 35 | M32: =Constiuence!Q792 -> 17 | N32: =SUM(C32:M32) -> 7253 | O32: 0 | P32: 55 | Q32: =N32+P32+O32 -> 7308 | R32: 0
A33: 25 | B33: Round-25 | C33: =Constiuence!Q816 -> 1429 | D33: =Constiuence!Q817 -> 3901 | E33: =Constiuence!Q818 -> 2627 | F33: =Constiuence!Q819 -> 56 | G33: =Constiuence!Q820 -> 10 | H33: =Constiuence!Q821 -> 4 | I33: =Constiuence!Q822 -> 10 | J33: =Constiuence!Q823 -> 4 | K33: =Constiuence!Q824 -> 20 | L33: =Constiuence!Q825 -> 32 | M33: =Constiuence!Q826 -> 37 | N33: =SUM(C33:M33) -> 8130 | O33: 0 | P33: 55 | Q33: =N33+P33+O33 -> 8185 | R33: 0
A34: 26 | B34: Round-26 | C34: =Constiuence!Q850 -> 1379 | D34: =Constiuence!Q851 -> 1431 | E34: =Constiuence!Q852 -> 5782 | F34: =Constiuence!Q853 -> 40 | G34: =Constiuence!Q854 -> 6 | H34: =Constiuence!Q855 -> 4 | I34: =Constiuence!Q856 -> 7 | J34: =Constiuence!Q857 -> 16 | K34: =Constiuence!Q858 -> 13 | L34: =Constiuence!Q859 -> 49 | M34: =Constiuence!Q860 -> 20 | N34: =SUM(C34:M34) -> 8747 | O34: 0 | P34: 35 | Q34: =N34+P34+O34 -> 8782 | R34: 0
A35: 27 | B35: Round-27 | C35: =Constiuence!Q883 -> 1596 | D35: =Constiuence!Q884 -> 1962 | E35: =Constiuence!Q885 -> 4873 | F35: =Constiuence!Q886 -> 57 | G35: =Constiuence!Q887 -> 9 | H35: =Constiuence!Q888 -> 8 | I35: =Constiuence!Q889 -> 7 | J35: =Constiuence!Q890 -> 24 | K35: =Constiuence!Q891 -> 35 | L35: =Constiuence!Q892 -> 31 | M35: =Constiuence!Q893 -> 22 | N35: =SUM(C35:M35) -> 8624 | O35: 0 | P35: 34 | Q35: =N35+P35+O35 -> 8658 | R35: 0
A36: 28 | B36: Round-28 | C36: =Constiuence!Q916 -> 1576 | D36: =Constiuence!Q917 -> 1057 | E36: =Constiuence!Q918 -> 6232 | F36: =Constiuence!Q919 -> 70 | G36: =Constiuence!Q920 -> 5 | H36: =Constiuence!Q921 -> 7 | I36: =Constiuence!Q922 -> 5 | J36: =Constiuence!Q923 -> 13 | K36: =Constiuence!Q924 -> 5 | L36: =Constiuence!Q925 -> 46 | M36: =Constiuence!Q926 -> 14 | N36: =SUM(C36:M36) -> 9030 | O36: 0 | P36: 34 | Q36: =N36+P36+O36 -> 9064 | R36: 0
A37: 29 | B37: Round-29 | C37: =Constiuence!Q950 -> 693 | D37: =Constiuence!Q951 -> 2089 | E37: =Constiuence!Q952 -> 4483 | F37: =Constiuence!Q953 -> 51 | G37: =Constiuence!Q954 -> 6 | H37: =Constiuence!Q955 -> 2 | I37: =Constiuence!Q956 -> 4 | J37: =Constiuence!Q957 -> 9 | K37: =Constiuence!Q958 -> 31 | L37: =Constiuence!Q959 -> 58 | M37: =Constiuence!Q960 -> 9 | N37: =SUM(C37:M37) -> 7435 | O37: 0 | P37: 39 | Q37: =N37+P37+O37 -> 7474 | R37: 0
A38: 30 | B38: Round-30 | C38: =Constiuence!Q984 -> 1259 | D38: =Constiuence!Q985 -> 2599 | E38: =Constiuence!Q986 -> 4309 | F38: =Constiuence!Q987 -> 83 | G38: =Constiuence!Q988 -> 6 | H38: =Constiuence!Q989 -> 1 | I38: =Constiuence!Q990 -> 5 | J38: =Constiuence!Q991 -> 9 | K38: =Constiuence!Q992 -> 70 | L38: =Constiuence!Q993 -> 45 | M38: =Constiuence!Q994 -> 10 | N38: =SUM(C38:M38) -> 8396 | O38: 0 | P38: 27 | Q38: =N38+P38+O38 -> 8423 | R38: 0
A39: 31 | B39: Round-31 | C39: =Constiuence!Q1017 -> 592 | D39: =Constiuence!Q1018 -> 2229 | E39: =Constiuence!Q1019 -> 4245 | F39: =Constiuence!Q1020 -> 126 | G39: =Constiuence!Q1021 -> 5 | H39: =Constiuence!Q1022 -> 6 | I39: =Constiuence!Q1023 -> 3 | J39: =Constiuence!Q1024 -> 7 | K39: =Constiuence!Q1025 -> 60 | L39: =Constiuence!Q1026 -> 43 | M39: =Constiuence!Q1027 -> 15 | N39: =SUM(C39:M39) -> 7331 | O39: 0 | P39: 23 | Q39: =N39+P39+O39 -> 7354 | R39: 0
A40: 32 | B40: Round-32 | C40: =Constiuence!Q1050 -> 2488 | D40: =Constiuence!Q1051 -> 2004 | E40: =Constiuence!Q1052 -> 4631 | F40: =Constiuence!Q1053 -> 43 | G40: =Constiuence!Q1054 -> 7 | H40: =Constiuence!Q1055 -> 1 | I40: =Constiuence!Q1056 -> 12 | J40: =Constiuence!Q1057 -> 20 | K40: =Constiuence!Q1058 -> 10 | L40: =Constiuence!Q1059 -> 66 | M40: =Constiuence!Q1060 -> 19 | N40: =SUM(C40:M40) -> 9301 | O40: 0 | P40: 52 | Q40: =N40+P40+O40 -> 9353 | R40: 0
...

Sheet p-20 Hindi
A1: izk:i&20
A2: vfUre ifj.kke i=
A3: {fu;e 56lh¼2½lh}
A4: fo/kku lHkk fuokZpu {ks= dk lkekU; fuokZpu&2022
A6: fo/kkulHkk fuokZpu {ks= dh la[;k o uke&64 fldUnjkckn | H6: fo/kkulHkk fuokZpu {ks= esa dqy ernkrkvksa dh la[;k&397807
A8: erns; LFky dh la[;k | B8: erns; LFky dk uke | C8: fuEufyf[kr vH;fFkZ;ksa ds i{k esa fn;s x;s fof/kekU; erksa dh la[;k | N8: oS/k erksa dh dqy la[;k | O8: (Rejected) izfr{ksfir erksa dh la[;k | P8: uksVk fodYi ds fy;s er | Q8: dqy ;ksx | R8: ¼VsaMj½ fufonRr erksa dh la[;k
C9: euohj flag | D9: jkgqy ;kno | E9: y{eh jkt | F9: lyhe v[krj [kka | G9: vt; dqekj | H9: vt; dqekj 'kekZZ | I9: vfer flag rksej | J9: n'kZu 'kekZ | K9: fny'kkn vgen | L9: jktw Bkdqj | M9: ccyw
A10: 1 | B10: vdcjiqj >ks>k izkbejh Ldwy d-ua&1 | C10: 2 | D10: 599 | E10: 18 | F10: 3 | G10: 0 | H10: 0 | I10: 0 | J10: 0 | K10: 6 | L10: 2 | M10: 0 | N10: =SUM(C10:M10) -> 630 | O10: 0 | P10: 2 | Q10: =N10+P10-O10 -> 632 | R10: 0
A11: 2 | B11: vdcjiqj >ks>k izkbejh Ldwy d-ua&2 | C11: 48 | D11: 440 | E11: 42 | F11: 3 | G11: 1 | H11: 0 | I11: 1 | J11: 1 | K11: 5 | L11: 2 | M11: 3 | N11: =SUM(C11:M11) -> 546 | O11: 0 | P11: 1 | Q11: =N11+P11-O11 -> 547 | R11: 0
A12: 3 | B12: QStkckn fj<koyh izkbejh Ldwy | C12: 89 | D12: 15 | E12: 161 | F12: 1 | G12: 0 | H12: 0 | I12: 0 | J12: 0 | K12: 0 | L12: 2 | M12: 0 | N12: =SUM(C12:M12) -> 268 | O12: 0 | P12: 0 | Q12: =N12+P12-O12 -> 268 | R12: 0
A13: 4 | B13: ,sapkuk eqfLye Ldwy d-ua-&1 | C13: 94 | D13: 275 | E13: 34 | F13: 3 | G13: 2 | H13: 1 | I13: 1 | J13: 0 | K13: 56 | L13: 5 | M13: 0 | N13: =SUM(C13:M13) -> 471 | O13: 0 | P13: 3 | Q13: =N13+P13-O13 -> 474 | R13: 0
A14: 5 | B14: ,sapkuk eqfLye Ldwy d-ua-&2 | C14: 31 | D14: 306 | E14: 43 | F14: 3 | G14: 0 | H14: 0 | I14: 1 | J14: 2 | K14: 48 | L14: 2 | M14: 1 | N14: =SUM(C14:M14) -> 437 | O14: 0 | P14: 4 | Q14: =N14+P14-O14 -> 441 | R14: 0
A15: 6 | B15: mVljk izkbejh Ldwy d0u01 | C15: 30 | D15: 7 | E15: 342 | F15: 5 | G15: 7 | H15: 1 | I15: 1 | J15: 1 | K15: 0 | L15: 2 | M15: 1 | N15: =SUM(C15:M15) -> 397 | O15: 0 | P15: 2 | Q15: =N15+P15-O15 -> 399 | R15: 0
A16: 7 | B16: mVljk izkbejh Ldwy d0u02 | C16: 115 | D16: 16 | E16: 226 | F16: 3 | G16: 1 | H16: 2 | I16: 0 | J16: 5 | K16: 1 | L16: 2 | M16: 1 | N16: =SUM(C16:M16) -> 372 | O16: 0 | P16: 0 | Q16: =N16+P16-O16 -> 372 | R16: 0
A17: 8 | B17: cjeUnuxj izkbZejh Ldwy d-u-&1 | C17: 38 | D17: 45 | E17: 254 | F17: 5 | G17: 2 | H17: 0 | I17: 0 | J17: 1 | K17: 0 | L17: 1 | M17: 1 | N17: =SUM(C17:M17) -> 347 | O17: 0 | P17: 8 | Q17: =N17+P17-O17 -> 355 | R17: 0
A18: 9 | B18: cjeUnuxj izkbZejh Ldwy d-u-&2 | C18: 12 | D18: 46 | E18: 385 | F18: 2 | G18: 1 | H18: 0 | I18: 0 | J18: 1 | K18: 0 | L18: 3 | M18: 2 | N18: =SUM(C18:M18) -> 452 | O18: 0 | P18: 1 | Q18: =N18+P18-O18 -> 453 | R18: 0
A19: 10 | B19: cjeUnuxj izkbZejh Ldwy d-u-&3 | C19: 65 | D19: 85 | E19: 210 | F19: 4 | G19: 1 | H19: 0 | I19: 0 | J19: 0 | K19: 2 | L19: 1 | M19: 0 | N19: =SUM(C19:M19) -> 368 | O19: 0 | P19: 0 | Q19: =N19+P19-O19 -> 368 | R19: 0
A20: 11 | B20: fxj/kjiqj uoknk izkbejh Ldwy d-ua-&1 | C20: 151 | D20: 48 | E20: 197 | F20: 3 | G20: 1 | H20: 0 | I20: 0 | J20: 0 | K20: 0 | L20: 1 | M20: 0 | N20: =SUM(C20:M20) -> 401 | O20: 0 | P20: 4 | Q20: =N20+P20-O20 -> 405 | R20: 0
A21: 12 | B21: fxj/kjiqj uoknk izkbejh Ldwy d-ua-&2 | C21: 29 | D21: 79 | E21: 282 | F21: 3 | G21: 1 | H21: 0 | I21: 0 | J21: 0 | K21: 0 | L21: 3 | M21: 1 | N21: =SUM(C21:M21) -> 398 | O21: 0 | P21: 0 | Q21: =N21+P21-O21 -> 398 | R21: 0
... A481: 472 | B481: 'ks[kiqj eke izkbZejh Ldwy | C481: 36 | D481: 83 | E481: 398 | F481: 4 | G481: 0 | H481: 2 | I481: 0 | J481: 1 | K481: 0 | L481: 2 | M481: 0 | N481: =SUM(C481:M481) -> 526 | O481: 0 | P481: 0 | Q481: =N481+P481-O481 -> 526 | R481: 0
A482: ;ksx | C482: =SUM(C10:C481) -> 42351 | D482: =SUM(D10:D481) -> 95674 | E482: =SUM(E10:E481) -> 124620 | F482: =SUM(F10:F481) -> 2267 | G482: =SUM(G10:G481) -> 681 | H482: =SUM(H10:H481) -> 117 | I482: =SUM(I10:I481) -> 202 | J482: =SUM(J10:J481) -> 467 | ... M482: =SUM(M10:M481) -> 527 | N482: =SUM(C482:M482) -> 269977 | O482: =SUM(O10:O481) -> 0 | P482: =SUM(P10:P481) -> 1194 | Q482: =N482+P482-O482 -> 271171 | R482: =SUM(R10:R481) -> 0
A483: Mkd er i=ksa ij fjdkmZ fd;s x;s ernksa dh dqy la[;k | C483: 283 | D483: 627 | E483: 1024 | F483: 14 | G483: 4 | H483: 0 | I483: 1 | J483: 5 | K483: 1 | L483: 1 | M483: 1 | N483: =SUM(C483:M483) -> 1961 | O483: 696 | P483: 1 | Q483: =N483+P483+O483 -> 2658 | R483: 0
A484: Mkys x;s dqy erksa dh la[;k | C484: =SUM(C482:C483) -> 42634 | D484: =SUM(D482:D483) -> 96301 | E484: =SUM(E482:E483) -> 125644 | F484: =SUM(F482:F483) -> 2281 | G484: =SUM(G482:G483) -> 685 | H484: =SUM(H482:H483) -> 117 | I484: =SUM(I482:I483) -> 203 | J484: =SUM(J482:J483) -> 472 | ... M484: =SUM(M482:M483) -> 528 | N484: =SUM(C484:M484) -> 271938 | O484: =SUM(O482:O483) -> 696 | P484: =SUM(P482:P483) -> 1195 | Q484: =N484+P484+O484 -> 273829 | R484: =SUM(R482:R483) -> 0
N488: fjVfuZax vkWfQlj
N489: 64&fldUnjkckn fo/kkulHkk {ks=

Sheet 17G-1
D1: 17ग-1
A2: fo/kku lHkk fuokZpu {ks= dh la[;k o uke & 64 fldUnjkckn
A3: Vsfcy la[;k&1
A4: pdz la[;k&
A5: erns; LFky la[;k&
A6: dUVªksy ;wfuV dzekad&
A7: izekf.kr fd;k tkrk gS fd ge mDr x.kuk i`"B ¼1½ ls iw.kZr;k larq"V gS vkSj gesa x.kuk dk;Z ls fdlh izdkj dh dksbZ vkifr ugh gSA
A8: dza0la0 | B8: vH;FkhZ dk uke | C8: erx.kuk vfHkdrkZ dk uke | D8: iwjs gLrk{kj
A9: 1 | B9: 2 | C9: 3 | D9: 4
A10: 1 | B10: euohj flag
A11: 2 | B11: jkgqy ;kno
A12: 3 | B12: y{eh jkt
A13: 4 | B13: lyhe v[krj [kka
A14: 5 | B14: vt; dqekj
A15: 6 | B15: vt; dqekj 'kekZZ
A16: 7 | B16: vfer flag rksej
A17: 8 | B17: n'kZu 'kekZ
A18: 9 | B18: fny'kkn vgen
A19: 10 | B19: jktw Bkdqj
A20: 11 | B20: ccyw
A21: LFkku & e.Mh lfefr ifjlj] vuwi'kgj jksM] cqyUn'kgj
A22: fnukad& 10& ekpZ&2022
D28: fjVfuZax vkWfQlj
D29: fo/kkulHkk& 64 fldUnjkckn

Sheet 17G-2
A1: fo/kku lHkk lkekU; fuokZpu&2022
A2: izk:i& 17x dk Hkkx&2
A3: erx.kuk dk ifj.kke
A4: fo/kku lHkk fuokZpu {ks= dh la[;k o uke & 64 fldUnjkckn
A5: Vsfcy la[;k&
A6: pdz la[;k&
A7: erns; LFky la[;k&
A8: dUVªksy ;wfuV dzekad&
A9: dza0la0 | B9: vH;FkhZ dk uke | C9: dUVªksy ;wfuV esa fn[kk;s x;s erksa dh la[;k | D9: Hkkx&1 dh en la[;k&05 ds vuqlkj ?kVk;s tkus okys ijh{k.k erksa dh la[;k | E9: fof/kekU; erksa dh la[;k ¼3&4½
A10: 1 | B10: 2 | C10: 3 | D10: 4 | E10: 5
A11: ='17G-1'!A10 -> 1 | B11: ='17G-1'!B10 -> euohj flag
A12: ='17G-1'!A11 -> 2 | B12: ='17G-1'!B11 -> jkgqy ;kno
A13: ='17G-1'!A12 -> 3 | B13: ='17G-1'!B12 -> y{eh jkt
A14: ='17G-1'!A13 -> 4 | B14: ='17G-1'!B13 -> lyhe v[krj [kka
A15: ='17G-1'!A14 -> 5 | B15: ='17G-1'!B14 -> vt; dqekj
A16: ='17G-1'!A15 -> 6 | B16: ='17G-1'!B15 -> vt; dqekj 'kekZZ
A17: ='17G-1'!A16 -> 7 | B17: ='17G-1'!B16 -> vfer flag rksej
A18: ='17G-1'!A17 -> 8 | B18: ='17G-1'!B17 -> n'kZu 'kekZ
A19: ='17G-1'!A18 -> 9 | B19: ='17G-1'!B18 -> fny'kkn vgen
A20: ='17G-1'!A19 -> 10 | B20: ='17G-1'!B19 -> jktw Bkdqj
A21: ='17G-1'!A20 -> 11 | B21: ='17G-1'!B20 -> ccyw
A22: dqy ;ksx
A23: D;k mij nf'kZr erksa dh dqy la[;k Hkkx&1 dh en la[;k&6 esa fn[kk;s x;sa erksa dk dqy la[;k ls esy [kkrh gS vFkok nksuksa dh dqy la[;k esa dksbZ folaxfr ikbZ x;h gSA
A24: LFkku& e.Mh lfefr ifjlj] vuwi'kgj jksM] cqyUn'kgjA
A25: fnukad& 10& ekpZ&2022
D29: x.kuk i;Zos{kd ds gLrk{kj
D30: ¼iwjk uke&----------------------------------------------------½

Sheet PB-2
A1: FORMAT FOR RECORDING OF TALLY OF VOTES POLLED BY POSTAL BALLOT PAPPER WHEN COUNTED IN MORE THAN ONE TABLE
A2: Name of State/UT: Uttar Pradesh Table No-----------------
A3: No.& Name of Parliamentary/ Assembly Constitueney : 64 Sikandrabad
A4: Round No.---------------- (if Applicable)
A5: No. of Postal Ballots supplied to this Counting Table for Counting ---------------------
A6: S.No. | B6: Name of Candidate | C6: Party Affilliation | D6: Number of Votes Polled
A7: 1 | B7: 2 | C7: 3 | D7: 4
A8: 1
A9: 2
A10: 3
A11: 4
A12: 5
A13: 6
A14: 7
A15: 8
A16: 9
A17: 10
A18: 11
A19: 12
A20: 13
A21: Place- Mandi Samiti Paricer Anoopshahr Road Bulandshahr
A22: Date: 10-March-2022
D26: Returning Officer
D27: 64-Sikandrabad

Sheet All Data
A1: VIDHAN SABHA GENERAL ELECTION 2022
A2: No. & Name Assembly Constituency- 64 Sikandrabad
A3: District- Bulandshahr
A4: Ac. No. | B4: Polling Station | D4: Total No. of Electors | E4: Voters Turnout | I4: No. of voters identified using EPIC | J4: No. of Ten-dered Voters | K4: Manveer Singh | N4: Rahul Yadav | Q4: Lakshmi Raj | T4: Saleem Akhtar Khan | W4: Ajay Kumar | Z4: Ajay Kumar Sharma | AC4: Amit Singh Tomar | AF4: Darshan Sharma | AI4: Dilshad Ahmad | AL4: Raju Thakur | AO4: Bablu | AR4: Total voters Secured
B5: No. | C5: Name | E5: Male | F5: Female | G5: Other | H5: Total | K5: S.No. | L5: Party Affiliation | M5: Voters Secured | N5: S.No. | O5: Party Affiliation | P5: Voters Secured | Q5: S.No. | R5: Party Affiliation | S5: Voters Secured | T5: S.No. | U5: Party Affiliation | V5: Voters Secured | W5: S.No. | X5: Party Affiliation | Y5: Voters Secured | Z5: S.No. | AA5: Party Affiliation | AB5: Voters Secured | AC5: S.No. | AD5: Party Affiliation | AE5: Voters Secured | AF5: S.No. | AG5: Party Affiliation | AH5: Voters Secured | AI5: S.No. | AJ5: Party Affiliation | AK5: Voters Secured | AL5: S.No. | AM5: Party Affiliation | AN5: Voters Secured | AO5: S.No. | AP5: Party Affiliation | AQ5: Voters Secured
A6: 1 | B6: 2 | C6: 3 | D6: 4 | E6: 5 | F6: 6 | G6: 7 | H6: 8 | I6: 9 | J6: 10 | K6: 11 | L6: 12 | M6: 13 | N6: 14 | O6: 15 | P6: 16 | Q6: 17 | R6: 18 | S6: 19 | T6: 20 | U6: 21 | V6: 22 | W6: 23 | X6: 24 | Y6: 25 | Z6: 26 | AA6: 27 | AB6: 28 | AC6: 29 | AD6: 30 | AE6: 31 | AF6: 32 | AG6: 33 | AH6: 34 | AI6: 35 | AJ6: 36 | AK6: 37 | AL6: 38 | AM6: 39 | AN6: 40 | AO6: 41 | AP6: 42 | AQ6: 43 | AR6: 44
A7: 64 | B7: 1 | C7: vdcjiqj >ks>k izkbejh Ldwy d-ua&1 | D7: 1102 | E7: 347 | F7: 285 | G7: 0 | H7: =SUM(E7:G7) -> 632 | I7: 557 | J7: 0 | K7: 1 | L7: Bahujan Samaj Party | M7: ='Praroop-20 hindi'!C10 -> 2 | N7: 2 | O7: Samajwadi Party | P7: ='Praroop-20 hindi'!D10 -> 599 | Q7: 3 | R7: Bharatiya Janata Party | S7: ='Praroop-20 hindi'!E10 -> 18 | T7: 4 | U7: Indian National Congress | V7: ='Praroop-20 hindi'!F10 -> 3 | W7: 5 | X7: Lok Dal | Y7: ='Praroop-20 hindi'!G10 -> 0 | Z7: 6 | AA7: Loktantrik Janshakti Party | AB7: ='Praroop-20 hindi'!H10 -> 0 | AC7: 7 | AD7: Shiv Sena | AE7: ='Praroop-20 hindi'!I10 -> 0 | AF7: 8 | AG7: Aam Aadmi Party | AH7: ='Praroop-20 hindi'!J10 -> 0 | AI7: 9 | AJ7: All India Majlis-E- Ittehadul Muslimeen | AK7: ='Praroop-20 hindi'!K10 -> 6 | AL7: 10 | AM7: Rashtrawadi Janlok Party (Satya) | AN7: ='Praroop-20 hindi'!L10 -> 2 | AO7: 11 | AP7: Independent | AQ7: ='Praroop-20 hindi'!M10 -> 0 | AR7: =M7+P7+S7+V7+Y7+AB7+AE7+AH7+AK7+AN7+AQ7 -> 630
A8: 64 | B8: 2 | C8: vdcjiqj >ks>k izkbejh Ldwy d-ua&2 | D8: 1008 | E8: 266 | F8: 281 | G8: 0 | H8: =SUM(E8:G8) -> 547 | I8: 447 | J8: 0 | K8: 1 | M8: ='Praroop-20 hindi'!C11 -> 48 | N8: 2 | P8: ='Praroop-20 hindi'!D11 -> 440 | Q8: 3 | S8: ='Praroop-20 hindi'!E11 -> 42 | T8: 4 | V8: ='Praroop-20 hindi'!F11 -> 3 | W8: 5 | Y8: ='Praroop-20 hindi'!G11 -> 1 | Z8: 6 | AB8: ='Praroop-20 hindi'!H11 -> 0 | AC8: 7 | AE8: ='Praroop-20 hindi'!I11 -> 1 | AF8: 8 | AH8: ='Praroop-20 hindi'!J11 -> 1 | AI8: 9 | AK8: ='Praroop-20 hindi'!K11 -> 5 | AL8: 10 | AN8: ='Praroop-20 hindi'!L11 -> 2 | AO8: 11 | AQ8: ='Praroop-20 hindi'!M11 -> 3 | AR8: =M8+P8+S8+V8+Y8+AB8+AE8+AH8+AK8+AN8+AQ8 -> 546
A9: 64 | B9: 3 | C9: QStkckn fj<koyh izkbejh Ldwy | D9: 447 | E9: 138 | F9: 130 | G9: 0 | H9: =SUM(E9:G9) -> 268 | I9: 229 | J9: 0 | K9: 1 | M9: ='Praroop-20 hindi'!C12 -> 89 | N9: 2 | P9: ='Praroop-20 hindi'!D12 -> 15 | Q9: 3 | S9: ='Praroop-20 hindi'!E12 -> 161 | T9: 4 | V9: ='Praroop-20 hindi'!F12 -> 1 | W9: 5 | Y9: ='Praroop-20 hindi'!G12 -> 0 | Z9: 6 | AB9: ='Praroop-20 hindi'!H12 -> 0 | AC9: 7 | AE9: ='Praroop-20 hindi'!I12 -> 0 | AF9: 8 | AH9: ='Praroop-20 hindi'!J12 -> 0 | AI9: 9 | AK9: ='Praroop-20 hindi'!K12 -> 0 | AL9: 10 | AN9: ='Praroop-20 hindi'!L12 -> 2 | AO9: 11 | AQ9: ='Praroop-20 hindi'!M12 -> 0 | AR9: =M9+P9+S9+V9+Y9+AB9+AE9+AH9+AK9+AN9+AQ9 -> 268
A10: 64 | B10: 4 | C10: ,sapkuk eqfLye Ldwy d-ua-&1 | D10: 713 | E10: 253 | F10: 221 | G10: 0 | H10: =SUM(E10:G10) -> 474 | I10: 416 | J10: 0 | K10: 1 | M10: ='Praroop-20 hindi'!C13 -> 94 | N10: 2 | P10: ='Praroop-20 hindi'!D13 -> 275 | Q10: 3 | S10: ='Praroop-20 hindi'!E13 -> 34 | T10: 4 | V10: ='Praroop-20 hindi'!F13 -> 3 | W10: 5 | Y10: ='Praroop-20 hindi'!G13 -> 2 | Z10: 6 | AB10: ='Praroop-20 hindi'!H13 -> 1 | AC10: 7 | AE10: ='Praroop-20 hindi'!I13 -> 1 | AF10: 8 | AH10: ='Praroop-20 hindi'!J13 -> 0 | AI10: 9 | AK10: ='Praroop-20 hindi'!K13 -> 56 | AL10: 10 | AN10: ='Praroop-20 hindi'!L13 -> 5 | AO10: 11 | AQ10: ='Praroop-20 hindi'!M13 -> 0 | AR10: =M10+P10+S10+V10+Y10+AB10+AE10+AH10+AK10+AN10+AQ10 -> 471
A11: 64 | B11: 5 | C11: ,sapkuk eqfLye Ldwy d-ua-&2 | D11: 747 | E11: 210 | F11: 231 | G11: 0 | H11: =SUM(E11:G11) -> 441 | I11: 358 | J11: 0 | K11: 1 | M11: ='Praroop-20 hindi'!C14 -> 31 | N11: 2 | P11: ='Praroop-20 hindi'!D14 -> 306 | Q11: 3 | S11: ='Praroop-20 hindi'!E14 -> 43 | T11: 4 | V11: ='Praroop-20 hindi'!F14 -> 3 | W11: 5 | Y11: ='Praroop-20 hindi'!G14 -> 0 | Z11: 6 | AB11: ='Praroop-20 hindi'!H14 -> 0 | AC11: 7 | AE11: ='Praroop-20 hindi'!I14 -> 1 | AF11: 8 | AH11: ='Praroop-20 hindi'!J14 -> 2 | AI11: 9 | AK11: ='Praroop-20 hindi'!K14 -> 48 | AL11: 10 | AN11: ='Praroop-20 hindi'!L14 -> 2 | AO11: 11 | AQ11: ='Praroop-20 hindi'!M14 -> 1 | AR11: =M11+P11+S11+V11+Y11+AB11+AE11+AH11+AK11+AN11+AQ11 -> 437
A12: 64 | B12: 6 | C12: mVljk izkbejh Ldwy d0u01 | D12: 602 | E12: 203 | F12: 196 | G12: 0 | H12: =SUM(E12:G12) -> 399 | I12: 360 | J12: 0 | K12: 1 | M12: ='Praroop-20 hindi'!C15 -> 30 | N12: 2 | P12: ='Praroop-20 hindi'!D15 -> 7 | Q12: 3 | S12: ='Praroop-20 hindi'!E15 -> 342 | T12: 4 | V12: ='Praroop-20 hindi'!F15 -> 5 | W12: 5 | Y12: ='Praroop-20 hindi'!G15 -> 7 | Z12: 6 | AB12: ='Praroop-20 hindi'!H15 -> 1 | AC12: 7 | AE12: ='Praroop-20 hindi'!I15 -> 1 | AF12: 8 | AH12: ='Praroop-20 hindi'!J15 -> 1 | AI12: 9 | AK12: ='Praroop-20 hindi'!K15 -> 0 | AL12: 10 | AN12: ='Praroop-20 hindi'!L15 -> 2 | AO12: 11 | AQ12: ='Praroop-20 hindi'!M15 -> 1 | AR12: =M12+P12+S12+V12+Y12+AB12+AE12+AH12+AK12+AN12+AQ12 -> 397
A13: 64 | B13: 7 | C13: mVljk izkbejh Ldwy d0u02 | D13: 594 | E13: 209 | F13: 163 | G13: 0 | H13: =SUM(E13:G13) -> 372 | I13: 372 | J13: 0 | K13: 1 | M13: ='Praroop-20 hindi'!C16 -> 115 | N13: 2 | P13: ='Praroop-20 hindi'!D16 -> 16 | Q13: 3 | S13: ='Praroop-20 hindi'!E16 -> 226 | T13: 4 | V13: ='Praroop-20 hindi'!F16 -> 3 | W13: 5 | Y13: ='Praroop-20 hindi'!G16 -> 1 | Z13: 6 | AB13: ='Praroop-20 hindi'!H16 -> 2 | AC13: 7 | AE13: ='Praroop-20 hindi'!I16 -> 0 | AF13: 8 | AH13: ='Praroop-20 hindi'!J16 -> 5 | AI13: 9 | AK13: ='Praroop-20 hindi'!K16 -> 1 | AL13: 10 | AN13: ='Praroop-20 hindi'!L16 -> 2 | AO13: 11 | AQ13: ='Praroop-20 hindi'!M16 -> 1 | AR13: =M13+P13+S13+V13+Y13+AB13+AE13+AH13+AK13+AN13+AQ13 -> 372
A14: 64 | B14: 8 | C14: cjeUnuxj izkbZejh Ldwy d-u-&1 | D14: 756 | E14: 215 | F14: 140 | G14: 0 | H14: =SUM(E14:G14) -> 355 | I14: 332 | J14: 0 | K14: 1 | M14: ='Praroop-20 hindi'!C17 -> 38 | N14: 2 | P14: ='Praroop-20 hindi'!D17 -> 45 | Q14: 3 | S14: ='Praroop-20 hindi'!E17 -> 254 | T14: 4 | V14: ='Praroop-20 hindi'!F17 -> 5 | W14: 5 | Y14: ='Praroop-20 hindi'!G17 -> 2 | Z14: 6 | AB14: ='Praroop-20 hindi'!H17 -> 0 | AC14: 7 | AE14: ='Praroop-20 hindi'!I17 -> 0 | AF14: 8 | AH14: ='Praroop-20 hindi'!J17 -> 1 | AI14: 9 | AK14: ='Praroop-20 hindi'!K17 -> 0 | AL14: 10 | AN14: ='Praroop-20 hindi'!L17 -> 1 | AO14: 11 | AQ14: ='Praroop-20 hindi'!M17 -> 1 | AR14: =M14+P14+S14+V14+Y14+AB14+AE14+AH14+AK14+AN14+AQ14 -> 347
A15: 64 | B15: 9 | C15: cjeUnuxj izkbZejh Ldwy d-u-&2 | D15: 803 | E15: 285 | F15: 168 | G15: 0 | H15: =SUM(E15:G15) -> 453 | I15: 411 | J15: 0 | K15: 1 | M15: ='Praroop-20 hindi'!C18 -> 12 | N15: 2 | P15: ='Praroop-20 hindi'!D18 -> 46 | Q15: 3 | S15: ='Praroop-20 hindi'!E18 -> 385 | T15: 4 | V15: ='Praroop-20 hindi'!F18 -> 2 | W15: 5 | Y15: ='Praroop-20 hindi'!G18 -> 1 | Z15: 6 | AB15: ='Praroop-20 hindi'!H18 -> 0 | AC15: 7 | AE15: ='Praroop-20 hindi'!I18 -> 0 | AF15: 8 | AH15: ='Praroop-20 hindi'!J18 -> 1 | AI15: 9 | AK15: ='Praroop-20 hindi'!K18 -> 0 | AL15: 10 | AN15: ='Praroop-20 hindi'!L18 -> 3 | AO15: 11 | AQ15: ='Praroop-20 hindi'!M18 -> 2 | AR15: =M15+P15+S15+V15+Y15+AB15+AE15+AH15+AK15+AN15+AQ15 -> 452
