Workbook

Sheet POSTAL BALLOT H
A1: fo/kku lHkk lkekU; fuokZpu&2022&Mkd eri=ksa dk fooj.k
A2: dza0la0 | B2: fo/kku lHkk fuokZpu {ks= dk uke | C2: lsok ernkrkvksa ds laca/k esa fooj.k | F2: ernku dkfeZdksa ds laca/k esa fooj.k
C3: lsok ernkrkvksa dh dqy la[;k | D3: lsok ernkrkvksa dks tkjh fd;s x;s Mkd eri=ksa dh dqy la[;k | E3: lsok ernkrkvksa ls okil izkIr gq, Mkd eri=ksa dh dqy la[;k | F3: ernku dkfeZdksa dh dqy la[;k ¼flfoy$iqfyl½ tks fuokZpu M;wVh ij rSukr gS ,oa Mkd eri= ds fy, vf/kd`r gSA | G3: mDr ernku dkfeZdksa dks tkjh fd;s x;s Mkd eri=ksa dh dqy la[;k | H3: mDr ernku dkfeZdksa ls okil izkIr gq, Mkd eri=ksa dh dqy la[;k
A4: 1 | B4: 2 | C4: 3 | D4: 4 | E4: 5 | F4: 6 | G4: 7 | H4: 8
A5: 1 | B5: 66 L;kuk
A6: dqy ;ksx
A7: LFkku & e.Mh lfefr ifjlj] vuwi'kgj jksM] cqyUn'kgj
A8: fnukad& 10& ekpZ&2022
G11: fjVfuZax vkWfQlj
G12: fo/kkulHkk& 66 L;kuk

Sheet POSTAL BALLOT 1 (2)
A1: FORMAT FOR RECORDING OF TALLY OF POSTAL BALLOTS ISSUED TO SERVICE PERSONNEL AND RECEIVED BACK
A2: Name of State/UT: Uttar Pradesh
A3: No.& Name of Parliamentary/ Assembly Constitueney : 66 Syana
A4: Total Electors in the last part of electoral Roll | B4: No of CSVs if any (who have appointed proxy) | C4: Total no of PBs issued | D4: PBs received back in time (before the date & time fixed for counting of votes) | E4: PBs received back undelivered
A5: 1 | B5: 2 | C5: 3 | D5: 4 | E5: 5
A22: Place- Mandi Samiti Paricer Anoopshahr Road Bulandshahr
A23: Date: 10-March-2022
E26: Returning Officer
E27: 66-Syana

Sheet POSTAL BALLOT 1
A1: FORMAT FOR RECORDING OF TALLY OF VOTES POLLED BY POSTAL BALLOT PAPPER WHEN COUNTED IN MORE THAN ONE TABLE
A2: Name of State/UT: Uttar Pradesh Table No-----------------
A3: No.& Name of Parliamentary/ Assembly Constitueney : 66 Syana
A4: Round No.---------------- (if Applicable)
A5: No. of Postal Ballots supplied to this Counting Table for Counting ---------------------
A6: S.No. | B6: Name of Candidate | C6: Party Affilliation | D6: Number of Votes Polled
A7: 1 | B7: 2 | C7: 3 | D7: 4
A8: 1 | B8: Dilnawaz Khan | C8: Rashtriya Lokdal
A9: 2 | B9: Devendra Singh Lodhi | C9: Bharatiya Janata Party
A10: 3 | B10: Km. Poonam | C10: Indian National Congress
A11: 4 | B11: Sunil Kumar | C11: Bahujan Samaj Party
A12: 5 | B12: Satvir Singh | C12: Aam Aadmi Party
A13: 6 | B13: Gyanesh Kumar Chauhan | C13: Hindustan Uttan Party
A14: 7 | B14: Dinesh | C14: Independent
A15: 8 | B15: Sangeeta | C15: Independent
A16: 9 | B16: NOTA
A17: 10 | B17: Rejected Votes
A18: Place- Mandi Samiti Paricer Anoopshahr Road Bulandshahr
A19: Date: 10-March-2022
D23: Returning Officer
D24: 66-Syana

Sheet PRARUP- 17G- 2
A1: fo/kku lHkk fuokZpu {ks= dh la[;k o uke & 66 L;kuk
A2: Vsfcy la[;k&1
A3: pdz la[;k&
A4: erns; LFky la[;k&
A5: dUVªksy ;wfuV dzekad&
A6: izekf.kr fd;k tkrk gS fd ge mDr x.kuk i`"B ¼1½ ls iw.kZr;k larq"V gS vkSj gesa x.kuk dk;Z ls fdlh izdkj dh dksbZ vkifr ugh gSA
A7: dza0la0 | B7: vH;FkhZ dk uke | C7: erx.kuk vfHkdrkZ dk uke | D7: iwjs gLrk{kj
A8: 1 | B8: 2 | C8: 3 | D8: 4
A9: 1 | B9: fnyuokt [kku
A10: 2 | B10: nsosUnz flag yks/kh
A11: 3 | B11: dq0 iwue
A12: 4 | B12: lquhy dqekj
A13: 5 | B13: lrohj flag
A14: 6 | B14: Kkus'k dqekj pkSgku
A15: 7 | B15: fnus'k
A16: 8 | B16: laxhrk
A17: LFkku & e.Mh lfefr ifjlj] vuwi'kgj jksM] cqyUn'kgj
A18: fnukad& 10& ekpZ&2022
D24: fjVfuZax vkWfQlj
D25: fo/kkulHkk& 66 L;kuk

Sheet PRARUP- 17G- 1
A1: fo/kku lHkk lkekU; fuokZpu&2022
A2: izk:i& 17x dk Hkkx&2
A3: erx.kuk dk ifj.kke
A4: fo/kku lHkk fuokZpu {ks= dh la[;k o uke & 66 L;kuk
A5: Vsfcy la[;k&
A6: pdz la[;k&
A7: erns; LFky la[;k&
A8: dUVªksy ;wfuV dzekad&
A9: dza0la0 | B9: vH;FkhZ dk uke | C9: dUVªksy ;wfuV esa fn[kk;s x;s erksa dh la[;k | D9: Hkkx&1 dh en la[;k&05 ds vuqlkj ?kVk;s tkus okys ijh{k.k erksa dh la[;k | E9: fof/kekU; erksa dh la[;k ¼3&4½
A10: 1 | B10: 2 | C10: 3 | D10: 4 | E10: 5
A11: 1 | B11: fnyuokt [kku
A12: 2 | B12: nsosUnz flag yks/kh
A13: 3 | B13: dq0 iwue
A14: 4 | B14: lquhy dqekj
A15: 5 | B15: lrohj flag
A16: 6 | B16: Kkus'k dqekj pkSgku
A17: 7 | B17: fnus'k
A18: 8 | B18: laxhrk
A19: 14 | B19: buesa ls dksbZ ugh ¼uksVk½
A20: dqy ;ksx
A21: D;k mij nf'kZr erksa dh dqy la[;k Hkkx&1 dh en la[;k&6 esa fn[kk;s x;sa erksa dk dqy la[;k ls esy [kkrh gS vFkok nksuksa dh dqy la[;k esa dksbZ folaxfr ikbZ x;h gSA
A22: LFkku& e.Mh lfefr ifjlj] vuwi'kgj jksM] cqyUn'kgjA
A23: fnukad& 10& ekpZ&2022
D27: x.kuk i;Zos{kd ds gLrk{kj
D28: ¼iwjk uke&----------------------------------------------------½

Sheet Refer Para 27
A1: Annexure for tabulating round-wise figures (Refer Para 27)
A2: Number & Name of Constituence - 66- SYANA | K2: Round No.1 | P2: Date | R2: 44630
A3: Table No. | C3: 1 | D3: 2 | E3: 3 | F3: 4 | G3: 5 | H3: 6 | I3: 7 | J3: 8 | K3: 9 | L3: 10 | M3: 11 | N3: 12 | O3: 13 | P3: 14 | Q3: Total | R3: Brought from Previous Round | S3: Cummulative Total
A4: Polling Booth No. | C4: 1 | D4: 2 | E4: 3 | F4: 4 | G4: 5 | H4: 6 | I4: 7 | J4: 8 | K4: 9 | L4: 10 | M4: 11 | N4: 12 | O4: 13 | P4: 14
A5: Control Unit No. | C5: ECUEC57730 | D5: ECUEC60998 | E5: ECUEC54512 | F5: ECUEC54315 | G5: ECUEC54992 | H5: ECUED23745 | I5: ECUEC64437 | J5: ECUEC57629 | K5: ECUED21307 | L5: ECUED24248 | M5: ECUEC47814 | N5: ECUEC54095 | O5: ECUEC54268 | P5: ECUED02725
A6: Number of Electors assigned to the polling Station | C6: 748 | D6: 663 | E6: 724 | F6: 495 | G6: 497 | H6: 750 | I6: 610 | J6: 796 | K6: 573 | L6: 634 | M6: 564 | N6: 507 | O6: 425 | P6: 492
A7: SI | B7: Name of Candidate | C7: - | D7: - | E7: - | F7: - | G7: - | H7: - | I7: - | J7: - | K7: - | L7: - | M7: - | N7: - | O7: - | P7: -
A8: 1 | B8: Dilnawaz Khan | C8: 258 | D8: 151 | E8: 45 | F8: 63 | G8: 67 | H8: 52 | I8: 28 | J8: 160 | K8: 161 | L8: 264 | M8: 200 | N8: 48 | O8: 213 | P8: 186 | Q8: =SUM(C8:P8) -> 1896 | R8: 0 | S8: =Q8+R8 -> 1896
A9: 2 | B9: Devendra Singh Lodhi | C9: 438 | D9: 197 | E9: 527 | F9: 339 | G9: 305 | H9: 666 | I9: 557 | J9: 613 | K9: 322 | L9: 321 | M9: 344 | N9: 319 | O9: 190 | P9: 138 | Q9: =SUM(C9:P9) -> 5276 | R9: 0 | S9: =Q9+R9 -> 5276
A10: 3 | B10: Km. Poonam | C10: 8 | D10: 10 | E10: 16 | F10: 18 | G10: 28 | H10: 9 | I10: 10 | J10: 13 | K10: 1 | L10: 2 | M10: 13 | N10: 8 | O10: 1 | P10: 3 | Q10: =SUM(C10:P10) -> 140 | R10: 0 | S10: =Q10+R10 -> 140
A11: 4 | B11: Sunil Kumar | C11: 35 | D11: 293 | E11: 95 | F11: 64 | G11: 75 | H11: 1 | I11: 7 | J11: 3 | K11: 78 | L11: 42 | M11: 4 | N11: 118 | O11: 12 | P11: 159 | Q11: =SUM(C11:P11) -> 986 | R11: 0 | S11: =Q11+R11 -> 986
A12: 5 | B12: Satvir Singh | C12: 1 | D12: 2 | E12: 5 | F12: 2 | G12: 0 | H12: 1 | I12: 1 | J12: 1 | K12: 2 | L12: 0 | M12: 1 | N12: 3 | O12: 0 | P12: 0 | Q12: =SUM(C12:P12) -> 19 | R12: 0 | S12: =Q12+R12 -> 19
A13: 6 | B13: Gyanesh Kumar Chauhan | C13: 2 | D13: 3 | E13: 6 | F13: 1 | G13: 2 | H13: 0 | I13: 2 | J13: 2 | K13: 2 | L13: 3 | M13: 1 | N13: 6 | O13: 0 | P13: 1 | Q13: =SUM(C13:P13) -> 31 | R13: 0 | S13: =Q13+R13 -> 31
A14: 7 | B14: Dinesh | C14: 2 | D14: 6 | E14: 12 | F14: 0 | G14: 5 | H14: 4 | I14: 1 | J14: 1 | K14: 1 | L14: 0 | M14: 0 | N14: 5 | O14: 2 | P14: 2 | Q14: =SUM(C14:P14) -> 41 | R14: 0 | S14: =Q14+R14 -> 41
A15: 8 | B15: Sangeeta | C15: 2 | D15: 0 | E15: 11 | F15: 6 | G15: 9 | H15: 7 | I15: 2 | J15: 2 | K15: 4 | L15: 0 | M15: 0 | N15: 0 | O15: 1 | P15: 2 | Q15: =SUM(C15:P15) -> 46 | R15: 0 | S15: =Q15+R15 -> 46
A16: 9 | B16: NOTA | C16: 2 | D16: 1 | E16: 7 | F16: 2 | G16: 6 | H16: 10 | I16: 2 | J16: 1 | K16: 2 | L16: 2 | M16: 1 | N16: 0 | O16: 6 | P16: 1 | Q16: =SUM(C16:P16) -> 43 | R16: 0 | S16: =Q16+R16 -> 43
A17: Rejected Votes | C17: 0 | D17: 0 | E17: 0 | F17: 0 | G17: 0 | H17: 0 | I17: 0 | J17: 0 | K17: 0 | L17: 0 | M17: 0 | N17: 0 | O17: 0 | P17: 0 | Q17: =SUM(C17:P17) -> 0 | R17: 0 | S17: =Q17+R17 -> 0
A18: Total Votes | C18: =SUM(C8:C16) -> 748 | D18: =SUM(D8:D16) -> 663 | E18: =SUM(E8:E16) -> 724 | F18: =SUM(F8:F16) -> 495 | G18: =SUM(G8:G16) -> 497 | H18: =SUM(H8:H16) -> 750 | I18: =SUM(I8:I16) -> 610 | J18: =SUM(J8:J16) -> 796 | ... S18: =SUM(S8:S16) -> 8478
C20: Initial of RO | D20: Initial of RO | E20: Initial of RO | F20: Initial of RO | G20: Initial of RO | H20: Initial of RO | I20: Initial of RO | J20: Initial of RO | K20: Initial of RO | L20: Initial of RO | M20: Initial of RO | N20: Initial of RO | O20: Initial of RO | P20: Initial of RO | Q20: Initial of RO | R20: Initial of RO | S20: Initial of RO
C22: Initial of observer | D22: Initial of observer | E22: Initial of observer | F22: Initial of observer | G22: Initial of observer | H22: Initial of observer | I22: Initial of observer | J22: Initial of observer | K22: Initial of observer | L22: Initial of observer | M22: Initial of observer | N22: Initial of observer | O22: Initial of observer | P22: Initial of observer | Q22: Initial of observer | R22: Initial of observer | S22: Initial of observer
A24: Important :- | C24: 1. All overwritings/cuttings should be certified by observer.
C25: 2. Polling station number whose votes are counted should be indicated below the table number.
C26: 3. The EVM (CU) no. used in the polling station will be specifically verified and tick marked by the form Part II of 17C
C27: 4. A copy of this is to be kept by observer in a separate folder for cross checking later.
B28: Note:- | C28: This is not final.The result of this report is subjected to approval of concern RO and Observer.
A30: Annexure for tabulating round-wise figures (Refer Para 27)
A31: Number & Name of Constituence - 66- SYANA | K31: Round No.2 | P31: Date | R31: 44630
A32: Table No. | C32: 1 | D32: 2 | E32: 3 | F32: 4 | G32: 5 | H32: 6 | I32: 7 | J32: 8 | K32: 9 | L32: 10 | M32: 11 | N32: 12 | O32: 13 | P32: 14 | Q32: Total | R32: Brought from Previous Round | S32: Cummulative Total
A33: Polling Booth No. | C33: 15 | D33: 16 | E33: 17 | F33: 18 | G33: 19 | H33: 20 | I33: 21 | J33: 22 | K33: 23 | L33: 24 | M33: 25 | N33: 26 | O33: 27 | P33: 28
A34: Control Unit No. | C34: ECUEC57731 | D34: ECUEC67183 | E34: ECUEC47929 | F34: ECUEC50247 | G34: ECUEC57828 | H34: ECUEC60512 | I34: ECUEC57060 | J34: ECUEC50277 | K34: ECUEC64586 | L34: ECUEC64297 | M34: ECUEC57441 | N34: ECUEC56097 | O34: ECUEC67396 | P34: ECUEC64598
A35: Number of Electors assigned to the polling Station | C35: 633 | D35: 739 | E35: 391 | F35: 324 | G35: 617 | H35: 574 | I35: 527 | J35: 620 | K35: 519 | L35: 455 | M35: 650 | N35: 696 | O35: 581 | P35: 683
A36: SI | B36: Name of Candidate | C36: - | D36: - | E36: - | F36: - | G36: - | H36: - | I36: - | J36: - | K36: - | L36: - | M36: - | N36: - | O36: - | P36: -
A37: 1 | B37: Dilnawaz Khan | C37: 170 | D37: 44 | E37: 179 | F37: 133 | G37: 234 | H37: 113 | I37: 126 | J37: 63 | K37: 23 | L37: 26 | M37: 195 | N37: 313 | O37: 157 | P37: 78 | Q37: =SUM(C37:P37) -> 1854 | R37: =S8 -> 1896 | S37: =Q37+R37 -> 3750
A38: 2 | B38: Devendra Singh Lodhi | C38: 379 | D38: 601 | E38: 199 | F38: 157 | G38: 196 | H38: 167 | I38: 188 | J38: 321 | K38: 392 | L38: 398 | M38: 443 | N38: 367 | O38: 379 | P38: 199 | Q38: =SUM(C38:P38) -> 4386 | R38: =S9 -> 5276 | S38: =Q38+R38 -> 9662
A39: 3 | B39: Km. Poonam | C39: 10 | D39: 7 | E39: 4 | F39: 2 | G39: 2 | H39: 0 | I39: 3 | J39: 6 | K39: 6 | L39: 6 | M39: 4 | N39: 1 | O39: 14 | P39: 7 | Q39: =SUM(C39:P39) -> 72 | R39: =S10 -> 140 | S39: =Q39+R39 -> 212
A40: 4 | B40: Sunil Kumar | C40: 59 | D40: 63 | E40: 2 | F40: 30 | G40: 174 | H40: 281 | I40: 206 | J40: 215 | K40: 92 | L40: 9 | M40: 4 | N40: 7 | O40: 14 | P40: 371 | Q40: =SUM(C40:P40) -> 1527 | R40: =S11 -> 986 | S40: =Q40+R40 -> 2513
A41: 5 | B41: Satvir Singh | C41: 2 | D41: 10 | E41: 0 | F41: 0 | G41: 0 | H41: 3 | I41: 1 | J41: 2 | K41: 0 | L41: 2 | M41: 0 | N41: 1 | O41: 6 | P41: 10 | Q41: =SUM(C41:P41) -> 37 | R41: =S12 -> 19 | S41: =Q41+R41 -> 56
A42: 6 | B42: Gyanesh Kumar Chauhan | C42: 3 | D42: 1 | E42: 5 | F42: 0 | G42: 5 | H42: 5 | I42: 0 | J42: 5 | K42: 2 | L42: 4 | M42: 1 | N42: 0 | O42: 2 | P42: 9 | Q42: =SUM(C42:P42) -> 42 | R42: =S13 -> 31 | S42: =Q42+R42 -> 73
A43: 7 | B43: Dinesh | C43: 1 | D43: 1 | E43: 0 | F43: 1 | G43: 2 | H43: 1 | I43: 1 | J43: 4 | K43: 2 | L43: 8 | M43: 0 | N43: 3 | O43: 3 | P43: 5 | Q43: =SUM(C43:P43) -> 32 | R43: =S14 -> 41 | S43: =Q43+R43 -> 73
A44: 8 | B44: Sangeeta | C44: 3 | D44: 4 | E44: 2 | F44: 0 | G44: 1 | H44: 4 | I44: 1 | J44: 1 | K44: 0 | L44: 1 | M44: 0 | N44: 1 | O44: 2 | P44: 1 | Q44: =SUM(C44:P44) -> 21 | R44: =S15 -> 46 | S44: =Q44+R44 -> 67
...

Sheet round-wise
A1: izk:Ik & 20
A2: vfUre ifj.kke&Ik=
A3: fu;e 56 lh ¼2½ lh
A4: fo/kkulHkk fuokZpu {ks= dk lkekU; fuokZpu&2022
A5: Hkkx&1
A6: fo/kku lHkk [k.M dk uke & 66 & L;kuk | H6: fo/kku lHkk fuokZpu {ks= es dqy ernkrkvksa dh la[;k & 385012
A7: dz0la0 | B7: jkm.M la[;k | C7: fnyuokt [kku | D7: nsosUnz flag yks/kh | E7: dq0 iwue | F7: lquhy dqekj | G7: lrohj flag | H7: Kkus'k dqekj pkSgku | I7: fnus'k | J7: laxhrk | K7: buesa ls dksbZ ugh ¼uksVk½ | L7: dqy fof/kekU; er | M7: (Rejected) izfr{ksfir erksa dh la[;k | N7: ;ksx | O7: ¼VsaMj½ fufonRr erksa dh la[;k
C8: 1 | D8: 2 | E8: 3 | F8: 4 | G8: 5 | H8: 6 | I8: 7 | J8: 8 | K8: 9
A9: 1 | B9: Round-1 | C9: ='Refer Para 27'!Q8 -> 1896 | D9: ='Refer Para 27'!Q9 -> 5276 | E9: ='Refer Para 27'!Q10 -> 140 | F9: ='Refer Para 27'!Q11 -> 986 | G9: ='Refer Para 27'!Q12 -> 19 | H9: ='Refer Para 27'!Q13 -> 31 | I9: ='Refer Para 27'!Q14 -> 41 | J9: ='Refer Para 27'!Q15 -> 46 | K9: ='Refer Para 27'!Q16 -> 43 | L9: =SUM(C9:K9) -> 8478 | M9: 0 | N9: =L9-M9 -> 8478 | O9: 0
A10: 2 | B10: Round-2 | C10: ='Refer Para 27'!Q37 -> 1854 | D10: ='Refer Para 27'!Q38 -> 4386 | E10: ='Refer Para 27'!Q39 -> 72 | F10: ='Refer Para 27'!Q40 -> 1527 | G10: ='Refer Para 27'!Q41 -> 37 | H10: ='Refer Para 27'!Q42 -> 42 | I10: ='Refer Para 27'!Q43 -> 32 | J10: ='Refer Para 27'!Q44 -> 21 | K10: ='Refer Para 27'!Q45 -> 38 | L10: =SUM(C10:K10) -> 8009 | M10: 0 | N10: =L10-M10 -> 8009 | O10: 0
A11: 3 | B11: Round-3 | C11: ='Refer Para 27'!Q66 -> 2757 | D11: ='Refer Para 27'!Q67 -> 3954 | E11: ='Refer Para 27'!Q68 -> 51 | F11: ='Refer Para 27'!Q69 -> 1270 | G11: ='Refer Para 27'!Q70 -> 19 | H11: ='Refer Para 27'!Q71 -> 18 | I11: ='Refer Para 27'!Q72 -> 35 | J11: ='Refer Para 27'!Q73 -> 16 | K11: ='Refer Para 27'!Q74 -> 30 | L11: =SUM(C11:K11) -> 8150 | M11: 0 | N11: =L11-M11 -> 8150 | O11: 0
A12: 4 | B12: Round-4 | C12: ='Refer Para 27'!Q95 -> 2049 | D12: ='Refer Para 27'!Q96 -> 4637 | E12: ='Refer Para 27'!Q97 -> 81 | F12: ='Refer Para 27'!Q98 -> 1170 | G12: ='Refer Para 27'!Q99 -> 13 | H12: ='Refer Para 27'!Q100 -> 17 | I12: ='Refer Para 27'!Q101 -> 26 | J12: ='Refer Para 27'!Q102 -> 28 | K12: ='Refer Para 27'!Q103 -> 54 | L12: =SUM(C12:K12) -> 8075 | M12: 0 | N12: =L12-M12 -> 8075 | O12: 0
A13: 5 | B13: Round-5 | C13: ='Refer Para 27'!Q124 -> 1632 | D13: ='Refer Para 27'!Q125 -> 4352 | E13: ='Refer Para 27'!Q126 -> 85 | F13: ='Refer Para 27'!Q127 -> 1673 | G13: ='Refer Para 27'!Q128 -> 25 | H13: ='Refer Para 27'!Q129 -> 40 | I13: ='Refer Para 27'!Q130 -> 28 | J13: ='Refer Para 27'!Q131 -> 30 | K13: ='Refer Para 27'!Q132 -> 34 | L13: =SUM(C13:K13) -> 7899 | M13: 0 | N13: =L13-M13 -> 7899 | O13: 0
A14: 6 | B14: Round-6 | C14: ='Refer Para 27'!Q153 -> 1511 | D14: ='Refer Para 27'!Q154 -> 4937 | E14: ='Refer Para 27'!Q155 -> 144 | F14: ='Refer Para 27'!Q156 -> 1660 | G14: ='Refer Para 27'!Q157 -> 26 | H14: ='Refer Para 27'!Q158 -> 51 | I14: ='Refer Para 27'!Q159 -> 47 | J14: ='Refer Para 27'!Q160 -> 25 | K14: ='Refer Para 27'!Q161 -> 25 | L14: =SUM(C14:K14) -> 8426 | M14: 0 | N14: =L14-M14 -> 8426 | O14: 0
A15: 7 | B15: Round-7 | C15: ='Refer Para 27'!Q182 -> 1427 | D15: ='Refer Para 27'!Q183 -> 5112 | E15: ='Refer Para 27'!Q184 -> 101 | F15: ='Refer Para 27'!Q185 -> 1037 | G15: ='Refer Para 27'!Q186 -> 20 | H15: ='Refer Para 27'!Q187 -> 29 | I15: ='Refer Para 27'!Q188 -> 29 | J15: ='Refer Para 27'!Q189 -> 42 | K15: ='Refer Para 27'!Q190 -> 43 | L15: =SUM(C15:K15) -> 7840 | M15: 0 | N15: =L15-M15 -> 7840 | O15: 0
A16: 8 | B16: Round-8 | C16: ='Refer Para 27'!Q211 -> 1380 | D16: ='Refer Para 27'!Q212 -> 5695 | E16: ='Refer Para 27'!Q213 -> 73 | F16: ='Refer Para 27'!Q214 -> 1699 | G16: ='Refer Para 27'!Q215 -> 24 | H16: ='Refer Para 27'!Q216 -> 38 | I16: ='Refer Para 27'!Q217 -> 27 | J16: ='Refer Para 27'!Q218 -> 29 | K16: ='Refer Para 27'!Q219 -> 28 | L16: =SUM(C16:K16) -> 8993 | M16: 0 | N16: =L16-M16 -> 8993 | O16: 0
A17: 9 | B17: Round-9 | C17: ='Refer Para 27'!Q240 -> 3402 | D17: ='Refer Para 27'!Q241 -> 3636 | E17: ='Refer Para 27'!Q242 -> 77 | F17: ='Refer Para 27'!Q243 -> 1610 | G17: ='Refer Para 27'!Q244 -> 27 | H17: ='Refer Para 27'!Q245 -> 20 | I17: ='Refer Para 27'!Q246 -> 24 | J17: ='Refer Para 27'!Q247 -> 26 | K17: ='Refer Para 27'!Q248 -> 47 | L17: =SUM(C17:K17) -> 8869 | M17: 0 | N17: =L17-M17 -> 8869 | O17: 0
A18: 10 | B18: Round-10 | C18: ='Refer Para 27'!Q269 -> 5414 | D18: ='Refer Para 27'!Q270 -> 2999 | E18: ='Refer Para 27'!Q271 -> 113 | F18: ='Refer Para 27'!Q272 -> 860 | G18: ='Refer Para 27'!Q273 -> 16 | H18: ='Refer Para 27'!Q274 -> 18 | I18: ='Refer Para 27'!Q275 -> 21 | J18: ='Refer Para 27'!Q276 -> 9 | K18: ='Refer Para 27'!Q277 -> 98 | L18: =SUM(C18:K18) -> 9548 | M18: 0 | N18: =L18-M18 -> 9548 | O18: 0
A19: 11 | B19: Round-11 | C19: ='Refer Para 27'!Q298 -> 1861 | D19: ='Refer Para 27'!Q299 -> 4893 | E19: ='Refer Para 27'!Q300 -> 76 | F19: ='Refer Para 27'!Q301 -> 1020 | G19: ='Refer Para 27'!Q302 -> 29 | H19: ='Refer Para 27'!Q303 -> 30 | I19: ='Refer Para 27'!Q304 -> 30 | J19: ='Refer Para 27'!Q305 -> 21 | K19: ='Refer Para 27'!Q306 -> 35 | L19: =SUM(C19:K19) -> 7995 | M19: 0 | N19: =L19-M19 -> 7995 | O19: 0
A20: 12 | B20: Round-12 | C20: ='Refer Para 27'!Q327 -> 1164 | D20: ='Refer Para 27'!Q328 -> 5137 | E20: ='Refer Para 27'!Q329 -> 74 | F20: ='Refer Para 27'!Q330 -> 815 | G20: ='Refer Para 27'!Q331 -> 64 | H20: ='Refer Para 27'!Q332 -> 62 | I20: ='Refer Para 27'!Q333 -> 31 | J20: ='Refer Para 27'!Q334 -> 18 | K20: ='Refer Para 27'!Q335 -> 22 | L20: =SUM(C20:K20) -> 7387 | M20: 0 | N20: =L20-M20 -> 7387 | O20: 0
A21: 13 | B21: Round-13 | C21: ='Refer Para 27'!Q356 -> 1128 | D21: ='Refer Para 27'!Q357 -> 4298 | E21: ='Refer Para 27'!Q358 -> 76 | F21: ='Refer Para 27'!Q359 -> 1465 | G21: ='Refer Para 27'!Q360 -> 10 | H21: ='Refer Para 27'!Q361 -> 142 | I21: ='Refer Para 27'!Q362 -> 19 | J21: ='Refer Para 27'!Q363 -> 25 | K21: ='Refer Para 27'!Q364 -> 32 | L21: =SUM(C21:K21) -> 7195 | M21: 0 | N21: =L21-M21 -> 7195 | O21: 0
A22: 14 | B22: Round-14 | C22: ='Refer Para 27'!Q385 -> 3151 | D22: ='Refer Para 27'!Q386 -> 3774 | E22: ='Refer Para 27'!Q387 -> 73 | F22: ='Refer Para 27'!Q388 -> 1325 | G22: ='Refer Para 27'!Q389 -> 25 | H22: ='Refer Para 27'!Q390 -> 26 | I22: ='Refer Para 27'!Q391 -> 27 | J22: ='Refer Para 27'!Q392 -> 33 | K22: ='Refer Para 27'!Q393 -> 40 | L22: =SUM(C22:K22) -> 8474 | M22: 0 | N22: =L22-M22 -> 8474 | O22: 0
A23: 15 | B23: Round-15 | C23: ='Refer Para 27'!Q414 -> 2194 | D23: ='Refer Para 27'!Q415 -> 4837 | E23: ='Refer Para 27'!Q416 -> 110 | F23: ='Refer Para 27'!Q417 -> 1365 | G23: ='Refer Para 27'!Q418 -> 15 | H23: ='Refer Para 27'!Q419 -> 39 | I23: ='Refer Para 27'!Q420 -> 33 | J23: ='Refer Para 27'!Q421 -> 52 | K23: ='Refer Para 27'!Q422 -> 35 | L23: =SUM(C23:K23) -> 8680 | M23: 0 | N23: =L23-M23 -> 8680 | O23: 0
A24: 16 | B24: Round-16 | C24: ='Refer Para 27'!Q443 -> 583 | D24: ='Refer Para 27'!Q444 -> 6785 | E24: ='Refer Para 27'!Q445 -> 156 | F24: ='Refer Para 27'!Q446 -> 1375 | G24: ='Refer Para 27'!Q447 -> 26 | H24: ='Refer Para 27'!Q448 -> 48 | I24: ='Refer Para 27'!Q449 -> 85 | J24: ='Refer Para 27'!Q450 -> 49 | K24: ='Refer Para 27'!Q451 -> 60 | L24: =SUM(C24:K24) -> 9167 | M24: 0 | N24: =L24-M24 -> 9167 | O24: 0
A25: 17 | B25: Round-17 | C25: ='Refer Para 27'!Q472 -> 2388 | D25: ='Refer Para 27'!Q473 -> 4194 | E25: ='Refer Para 27'!Q474 -> 54 | F25: ='Refer Para 27'!Q475 -> 771 | G25: ='Refer Para 27'!Q476 -> 14 | H25: ='Refer Para 27'!Q477 -> 11 | I25: ='Refer Para 27'!Q478 -> 33 | J25: ='Refer Para 27'!Q479 -> 34 | K25: ='Refer Para 27'!Q480 -> 36 | L25: =SUM(C25:K25) -> 7535 | M25: 0 | N25: =L25-M25 -> 7535 | O25: 0
A26: 18 | B26: Round-18 | C26: ='Refer Para 27'!Q501 -> 3667 | D26: ='Refer Para 27'!Q502 -> 4064 | E26: ='Refer Para 27'!Q503 -> 42 | F26: ='Refer Para 27'!Q504 -> 802 | G26: ='Refer Para 27'!Q505 -> 21 | H26: ='Refer Para 27'!Q506 -> 12 | I26: ='Refer Para 27'!Q507 -> 37 | J26: ='Refer Para 27'!Q508 -> 26 | K26: ='Refer Para 27'!Q509 -> 59 | L26: =SUM(C26:K26) -> 8730 | M26: 0 | N26: =L26-M26 -> 8730 | O26: 0
A27: 19 | B27: Round-19 | C27: ='Refer Para 27'!Q530 -> 1047 | D27: ='Refer Para 27'!Q531 -> 6370 | E27: ='Refer Para 27'!Q532 -> 83 | F27: ='Refer Para 27'!Q533 -> 535 | G27: ='Refer Para 27'!Q534 -> 19 | H27: ='Refer Para 27'!Q535 -> 27 | I27: ='Refer Para 27'!Q536 -> 56 | J27: ='Refer Para 27'!Q537 -> 56 | K27: ='Refer Para 27'!Q538 -> 54 | L27: =SUM(C27:K27) -> 8247 | M27: 0 | N27: =L27-M27 -> 8247 | O27: 0
A28: 20 | B28: Round-20 | C28: ='Refer Para 27'!Q559 -> 1282 | D28: ='Refer Para 27'!Q560 -> 5961 | E28: ='Refer Para 27'!Q561 -> 92 | F28: ='Refer Para 27'!Q562 -> 937 | G28: ='Refer Para 27'!Q563 -> 17 | H28: ='Refer Para 27'!Q564 -> 32 | I28: ='Refer Para 27'!Q565 -> 43 | J28: ='Refer Para 27'!Q566 -> 43 | K28: ='Refer Para 27'!Q567 -> 47 | L28: =SUM(C28:K28) -> 8454 | M28: 0 | N28: =L28-M28 -> 8454 | O28: 0
A29: 21 | B29: Round-21 | C29: ='Refer Para 27'!Q588 -> 831 | D29: ='Refer Para 27'!Q589 -> 5905 | E29: ='Refer Para 27'!Q590 -> 178 | F29: ='Refer Para 27'!Q591 -> 842 | G29: ='Refer Para 27'!Q592 -> 13 | H29: ='Refer Para 27'!Q593 -> 24 | I29: ='Refer Para 27'!Q594 -> 48 | J29: ='Refer Para 27'!Q595 -> 47 | K29: ='Refer Para 27'!Q596 -> 52 | L29: =SUM(C29:K29) -> 7940 | M29: 0 | N29: =L29-M29 -> 7940 | O29: 0
A30: 22 | B30: Round-22 | C30: ='Refer Para 27'!Q617 -> 985 | D30: ='Refer Para 27'!Q618 -> 4274 | E30: ='Refer Para 27'!Q619 -> 111 | F30: ='Refer Para 27'!Q620 -> 1230 | G30: ='Refer Para 27'!Q621 -> 13 | H30: ='Refer Para 27'!Q622 -> 20 | I30: ='Refer Para 27'!Q623 -> 21 | J30: ='Refer Para 27'!Q624 -> 27 | K30: ='Refer Para 27'!Q625 -> 19 | L30: =SUM(C30:K30) -> 6700 | M30: 0 | N30: =L30-M30 -> 6700 | O30: 0
A31: 23 | B31: Round-23 | C31: ='Refer Para 27'!Q646 -> 681 | D31: ='Refer Para 27'!Q647 -> 5931 | E31: ='Refer Para 27'!Q648 -> 58 | F31: ='Refer Para 27'!Q649 -> 1194 | G31: ='Refer Para 27'!Q650 -> 16 | H31: ='Refer Para 27'!Q651 -> 40 | I31: ='Refer Para 27'!Q652 -> 43 | J31: ='Refer Para 27'!Q653 -> 30 | K31: ='Refer Para 27'!Q654 -> 46 | L31: =SUM(C31:K31) -> 8039 | M31: 0 | N31: =L31-M31 -> 8039 | O31: 0
A32: 24 | B32: Round-24 | C32: ='Refer Para 27'!Q675 -> 777 | D32: ='Refer Para 27'!Q676 -> 4930 | E32: ='Refer Para 27'!Q677 -> 104 | F32: ='Refer Para 27'!Q678 -> 1181 | G32: ='Refer Para 27'!Q679 -> 33 | H32: ='Refer Para 27'!Q680 -> 59 | I32: ='Refer Para 27'!Q681 -> 35 | J32: ='Refer Para 27'!Q682 -> 39 | K32: ='Refer Para 27'!Q683 -> 54 | L32: =SUM(C32:K32) -> 7212 | M32: 0 | N32: =L32-M32 -> 7212 | O32: 0
A33: 25 | B33: Round-25 | C33: ='Refer Para 27'!Q704 -> 1167 | D33: ='Refer Para 27'!Q705 -> 5651 | E33: ='Refer Para 27'!Q706 -> 94 | F33: ='Refer Para 27'!Q707 -> 798 | G33: ='Refer Para 27'!Q708 -> 25 | H33: ='Refer Para 27'!Q709 -> 29 | I33: ='Refer Para 27'!Q710 -> 45 | J33: ='Refer Para 27'!Q711 -> 40 | K33: ='Refer Para 27'!Q712 -> 55 | L33: =SUM(C33:K33) -> 7904 | M33: 0 | N33: =L33-M33 -> 7904 | O33: 0
A34: 26 | B34: Round-26 | C34: ='Refer Para 27'!Q733 -> 905 | D34: ='Refer Para 27'!Q734 -> 4621 | E34: ='Refer Para 27'!Q735 -> 123 | F34: ='Refer Para 27'!Q736 -> 1293 | G34: ='Refer Para 27'!Q737 -> 31 | H34: ='Refer Para 27'!Q738 -> 36 | I34: ='Refer Para 27'!Q739 -> 41 | J34: ='Refer Para 27'!Q740 -> 29 | K34: ='Refer Para 27'!Q741 -> 35 | L34: =SUM(C34:K34) -> 7114 | M34: 0 | N34: =L34-M34 -> 7114 | O34: 0
A35: 27 | B35: Round-27 | C35: ='Refer Para 27'!Q762 -> 1223 | D35: ='Refer Para 27'!Q763 -> 4922 | E35: ='Refer Para 27'!Q764 -> 48 | F35: ='Refer Para 27'!Q765 -> 1037 | G35: ='Refer Para 27'!Q766 -> 18 | H35: ='Refer Para 27'!Q767 -> 37 | I35: ='Refer Para 27'!Q768 -> 38 | J35: ='Refer Para 27'!Q769 -> 45 | K35: ='Refer Para 27'!Q770 -> 59 | L35: =SUM(C35:K35) -> 7427 | M35: 0 | N35: =L35-M35 -> 7427 | O35: 0
A36: 28 | B36: Round-28 | C36: ='Refer Para 27'!Q791 -> 5380 | D36: ='Refer Para 27'!Q792 -> 1730 | E36: ='Refer Para 27'!Q793 -> 53 | F36: ='Refer Para 27'!Q794 -> 1294 | G36: ='Refer Para 27'!Q795 -> 40 | H36: ='Refer Para 27'!Q796 -> 26 | I36: ='Refer Para 27'!Q797 -> 28 | J36: ='Refer Para 27'!Q798 -> 24 | K36: ='Refer Para 27'!Q799 -> 65 | L36: =SUM(C36:K36) -> 8640 | M36: 0 | N36: =L36-M36 -> 8640 | O36: 0
A37: 29 | B37: Round-29 | C37: ='Refer Para 27'!Q820 -> 1915 | D37: ='Refer Para 27'!Q821 -> 4050 | E37: ='Refer Para 27'!Q822 -> 147 | F37: ='Refer Para 27'!Q823 -> 1095 | G37: ='Refer Para 27'!Q824 -> 23 | H37: ='Refer Para 27'!Q825 -> 151 | I37: ='Refer Para 27'!Q826 -> 41 | J37: ='Refer Para 27'!Q827 -> 34 | K37: ='Refer Para 27'!Q828 -> 52 | L37: =SUM(C37:K37) -> 7508 | M37: 0 | N37: =L37-M37 -> 7508 | O37: 0
A38: 30 | B38: Round-30 | C38: ='Refer Para 27'!Q849 -> 1927 | D38: ='Refer Para 27'!Q850 -> 4436 | E38: ='Refer Para 27'!Q851 -> 62 | F38: ='Refer Para 27'!Q852 -> 853 | G38: ='Refer Para 27'!Q853 -> 18 | H38: ='Refer Para 27'!Q854 -> 34 | I38: ='Refer Para 27'!Q855 -> 29 | J38: ='Refer Para 27'!Q856 -> 31 | K38: ='Refer Para 27'!Q857 -> 45 | L38: =SUM(C38:K38) -> 7435 | M38: 0 | N38: =L38-M38 -> 7435 | O38: 0
A39: 31 | B39: Round-31 | C39: ='Refer Para 27'!Q878 -> 1360 | D39: ='Refer Para 27'!Q879 -> 5179 | E39: ='Refer Para 27'!Q880 -> 106 | F39: ='Refer Para 27'!Q881 -> 925 | G39: ='Refer Para 27'!Q882 -> 26 | H39: ='Refer Para 27'!Q883 -> 35 | I39: ='Refer Para 27'!Q884 -> 31 | J39: ='Refer Para 27'!Q885 -> 29 | K39: ='Refer Para 27'!Q886 -> 54 | L39: =SUM(C39:K39) -> 7745 | M39: 0 | N39: =L39-M39 -> 7745 | O39: 0
A40: 32 | B40: Round-32 | C40: ='Refer Para 27'!Q907 -> 269 | D40: ='Refer Para 27'!Q908 -> 1416 | E40: ='Refer Para 27'!Q909 -> 31 | F40: ='Refer Para 27'!Q910 -> 399 | G40: ='Refer Para 27'!Q911 -> 6 | H40: ='Refer Para 27'!Q912 -> 11 | I40: ='Refer Para 27'!Q913 -> 5 | J40: ='Refer Para 27'!Q914 -> 5 | K40: ='Refer Para 27'!Q915 -> 4 | L40: =SUM(C40:K40) -> 2146 | M40: 0 | N40: =L40-M40 -> 2146 | O40: 0
...

Sheet 66 SYANA PRAROOP-20
A1: izk:Ik & 20
A2: vfUre ifj.kke&Ik=
A3: fu;e 56 lh ¼2½ lh
A4: fo/kkulHkk fuokZpu {ks= dk lkekU; fuokZpu&2022
A5: Hkkx&1
B6: fo/kku lHkk [k.M dk uke & 66 & L;kuk | G6: fo/kku lHkk fuokZpu {ks= es dqy ernkrkvksa dh la[;k & 385012
B7: iksfyax LVs'ku dh dze la[;k | C7: fnyuokt [kku | D7: nsosUnz flag yks/kh | E7: dq0 iwue | F7: lquhy dqekj | G7: lrohj flag | H7: Kkus'k dqekj pkSgku | I7: fnus'k | J7: laxhrk | K7: dqy fof/kekU; er | L7: (Rejected) izfr{ksfir erksa dh la[;k | M7: buesa ls dksbZ ugh ¼uksVk½ | N7: ;ksx | O7: ¼VsaMj½ fufonRr erksa dh la[;k
B8: 1 | C8: ='Refer Para 27'!C8 -> 258 | D8: ='Refer Para 27'!C9 -> 438 | E8: ='Refer Para 27'!C10 -> 8 | F8: ='Refer Para 27'!C11 -> 35 | G8: ='Refer Para 27'!C12 -> 1 | H8: ='Refer Para 27'!C13 -> 2 | I8: ='Refer Para 27'!C14 -> 2 | J8: ='Refer Para 27'!C15 -> 2 | K8: =SUM(C8:J8) -> 746 | L8: 0 | M8: ='Refer Para 27'!C16 -> 2 | N8: =K8+M8-L8 -> 748 | O8: 0
B9: 2 | C9: ='Refer Para 27'!D8 -> 151 | D9: ='Refer Para 27'!D9 -> 197 | E9: ='Refer Para 27'!D10 -> 10 | F9: ='Refer Para 27'!D11 -> 293 | G9: ='Refer Para 27'!D12 -> 2 | H9: ='Refer Para 27'!D13 -> 3 | I9: ='Refer Para 27'!D14 -> 6 | J9: ='Refer Para 27'!D15 -> 0 | K9: =SUM(C9:J9) -> 662 | L9: 0 | M9: ='Refer Para 27'!D16 -> 1 | N9: =K9+M9-L9 -> 663 | O9: 0
B10: 3 | C10: ='Refer Para 27'!E8 -> 45 | D10: ='Refer Para 27'!E9 -> 527 | E10: ='Refer Para 27'!E10 -> 16 | F10: ='Refer Para 27'!E11 -> 95 | G10: ='Refer Para 27'!E12 -> 5 | H10: ='Refer Para 27'!E13 -> 6 | I10: ='Refer Para 27'!E14 -> 12 | J10: ='Refer Para 27'!E15 -> 11 | K10: =SUM(C10:J10) -> 717 | L10: 0 | M10: ='Refer Para 27'!E16 -> 7 | N10: =K10+M10-L10 -> 724 | O10: 0
B11: 4 | C11: ='Refer Para 27'!F8 -> 63 | D11: ='Refer Para 27'!F9 -> 339 | E11: ='Refer Para 27'!F10 -> 18 | F11: ='Refer Para 27'!F11 -> 64 | G11: ='Refer Para 27'!F12 -> 2 | H11: ='Refer Para 27'!F13 -> 1 | I11: ='Refer Para 27'!F14 -> 0 | J11: ='Refer Para 27'!F15 -> 6 | K11: =SUM(C11:J11) -> 493 | L11: 0 | M11: ='Refer Para 27'!F16 -> 2 | N11: =K11+M11-L11 -> 495 | O11: 0
B12: 5 | C12: ='Refer Para 27'!G8 -> 67 | D12: ='Refer Para 27'!G9 -> 305 | E12: ='Refer Para 27'!G10 -> 28 | F12: ='Refer Para 27'!G11 -> 75 | G12: ='Refer Para 27'!G12 -> 0 | H12: ='Refer Para 27'!G13 -> 2 | I12: ='Refer Para 27'!G14 -> 5 | J12: ='Refer Para 27'!G15 -> 9 | K12: =SUM(C12:J12) -> 491 | L12: 0 | M12: ='Refer Para 27'!G16 -> 6 | N12: =K12+M12-L12 -> 497 | O12: 0
B13: 6 | C13: ='Refer Para 27'!H8 -> 52 | D13: ='Refer Para 27'!H9 -> 666 | E13: ='Refer Para 27'!H10 -> 9 | F13: ='Refer Para 27'!H11 -> 1 | G13: ='Refer Para 27'!H12 -> 1 | H13: ='Refer Para 27'!H13 -> 0 | I13: ='Refer Para 27'!H14 -> 4 | J13: ='Refer Para 27'!H15 -> 7 | K13: =SUM(C13:J13) -> 740 | L13: 0 | M13: ='Refer Para 27'!H16 -> 10 | N13: =K13+M13-L13 -> 750 | O13: 0
B14: 7 | C14: ='Refer Para 27'!I8 -> 28 | D14: ='Refer Para 27'!I9 -> 557 | E14: ='Refer Para 27'!I10 -> 10 | F14: ='Refer Para 27'!I11 -> 7 | G14: ='Refer Para 27'!I12 -> 1 | H14: ='Refer Para 27'!I13 -> 2 | I14: ='Refer Para 27'!I14 -> 1 | J14: ='Refer Para 27'!I15 -> 2 | K14: =SUM(C14:J14) -> 608 | L14: 0 | M14: ='Refer Para 27'!I16 -> 2 | N14: =K14+M14-L14 -> 610 | O14: 0
B15: 8 | C15: ='Refer Para 27'!J8 -> 160 | D15: ='Refer Para 27'!J9 -> 613 | E15: ='Refer Para 27'!J10 -> 13 | F15: ='Refer Para 27'!J11 -> 3 | G15: ='Refer Para 27'!J12 -> 1 | H15: ='Refer Para 27'!J13 -> 2 | I15: ='Refer Para 27'!J14 -> 1 | J15: ='Refer Para 27'!J15 -> 2 | K15: =SUM(C15:J15) -> 795 | L15: 0 | M15: ='Refer Para 27'!J16 -> 1 | N15: =K15+M15-L15 -> 796 | O15: 0
B16: 9 | C16: ='Refer Para 27'!K8 -> 161 | D16: ='Refer Para 27'!K9 -> 322 | E16: ='Refer Para 27'!K10 -> 1 | F16: ='Refer Para 27'!K11 -> 78 | G16: ='Refer Para 27'!K12 -> 2 | H16: ='Refer Para 27'!K13 -> 2 | I16: ='Refer Para 27'!K14 -> 1 | J16: ='Refer Para 27'!K15 -> 4 | K16: =SUM(C16:J16) -> 571 | L16: 0 | M16: ='Refer Para 27'!K16 -> 2 | N16: =K16+M16-L16 -> 573 | O16: 0
B17: 10 | C17: ='Refer Para 27'!L8 -> 264 | D17: ='Refer Para 27'!L9 -> 321 | E17: ='Refer Para 27'!L10 -> 2 | F17: ='Refer Para 27'!L11 -> 42 | G17: ='Refer Para 27'!L12 -> 0 | H17: ='Refer Para 27'!L13 -> 3 | I17: ='Refer Para 27'!L14 -> 0 | J17: ='Refer Para 27'!L15 -> 0 | K17: =SUM(C17:J17) -> 632 | L17: 0 | M17: ='Refer Para 27'!L16 -> 2 | N17: =K17+M17-L17 -> 634 | O17: 0
B18: 11 | C18: ='Refer Para 27'!M8 -> 200 | D18: ='Refer Para 27'!M9 -> 344 | E18: ='Refer Para 27'!M10 -> 13 | F18: ='Refer Para 27'!M11 -> 4 | G18: ='Refer Para 27'!M12 -> 1 | H18: ='Refer Para 27'!M13 -> 1 | I18: ='Refer Para 27'!M14 -> 0 | J18: ='Refer Para 27'!M15 -> 0 | K18: =SUM(C18:J18) -> 563 | L18: 0 | M18: ='Refer Para 27'!M16 -> 1 | N18: =K18+M18-L18 -> 564 | O18: 0
B19: 12 | C19: ='Refer Para 27'!N8 -> 48 | D19: ='Refer Para 27'!N9 -> 319 | E19: ='Refer Para 27'!N10 -> 8 | F19: ='Refer Para 27'!N11 -> 118 | G19: ='Refer Para 27'!N12 -> 3 | H19: ='Refer Para 27'!N13 -> 6 | I19: ='Refer Para 27'!N14 -> 5 | J19: ='Refer Para 27'!N15 -> 0 | K19: =SUM(C19:J19) -> 507 | L19: 0 | M19: ='Refer Para 27'!N16 -> 0 | N19: =K19+M19-L19 -> 507 | O19: 0
B20: 13 | C20: ='Refer Para 27'!O8 -> 213 | D20: ='Refer Para 27'!O9 -> 190 | E20: ='Refer Para 27'!O10 -> 1 | F20: ='Refer Para 27'!O11 -> 12 | G20: ='Refer Para 27'!O12 -> 0 | H20: ='Refer Para 27'!O13 -> 0 | I20: ='Refer Para 27'!O14 -> 2 | J20: ='Refer Para 27'!O15 -> 1 | K20: =SUM(C20:J20) -> 419 | L20: 0 | M20: ='Refer Para 27'!O16 -> 6 | N20: =K20+M20-L20 -> 425 | O20: 0
B21: 14 | C21: ='Refer Para 27'!P8 -> 186 | D21: ='Refer Para 27'!P9 -> 138 | E21: ='Refer Para 27'!P10 -> 3 | F21: ='Refer Para 27'!P11 -> 159 | G21: ='Refer Para 27'!P12 -> 0 | H21: ='Refer Para 27'!P13 -> 1 | I21: ='Refer Para 27'!P14 -> 2 | J21: ='Refer Para 27'!P15 -> 2 | K21: =SUM(C21:J21) -> 491 | L21: 0 | M21: ='Refer Para 27'!P16 -> 1 | N21: =K21+M21-L21 -> 492 | O21: 0
B22: 15 | C22: ='Refer Para 27'!C37 -> 170 | D22: ='Refer Para 27'!C38 -> 379 | E22: ='Refer Para 27'!C39 -> 10 | F22: ='Refer Para 27'!C40 -> 59 | G22: ='Refer Para 27'!C41 -> 2 | H22: ='Refer Para 27'!C42 -> 3 | I22: ='Refer Para 27'!C43 -> 1 | J22: ='Refer Para 27'!C44 -> 3 | K22: =SUM(C22:J22) -> 627 | L22: 0 | M22: ='Refer Para 27'!C45 -> 6 | N22: =K22+M22-L22 -> 633 | O22: 0
B23: 16 | C23: ='Refer Para 27'!D37 -> 44 | D23: ='Refer Para 27'!D38 -> 601 | E23: ='Refer Para 27'!D39 -> 7 | F23: ='Refer Para 27'!D40 -> 63 | G23: ='Refer Para 27'!D41 -> 10 | H23: ='Refer Para 27'!D42 -> 1 | I23: ='Refer Para 27'!D43 -> 1 | J23: ='Refer Para 27'!D44 -> 4 | K23: =SUM(C23:J23) -> 731 | L23: 0 | M23: ='Refer Para 27'!D45 -> 8 | N23: =K23+M23-L23 -> 739 | O23: 0
B24: 17 | C24: ='Refer Para 27'!E37 -> 179 | D24: ='Refer Para 27'!E38 -> 199 | E24: ='Refer Para 27'!E39 -> 4 | F24: ='Refer Para 27'!E40 -> 2 | G24: ='Refer Para 27'!E41 -> 0 | H24: ='Refer Para 27'!E42 -> 5 | I24: ='Refer Para 27'!E43 -> 0 | J24: ='Refer Para 27'!E44 -> 2 | K24: =SUM(C24:J24) -> 391 | L24: 0 | M24: ='Refer Para 27'!E45 -> 0 | N24: =K24+M24-L24 -> 391 | O24: 0
B25: 18 | C25: ='Refer Para 27'!F37 -> 133 | D25: ='Refer Para 27'!F38 -> 157 | E25: ='Refer Para 27'!F39 -> 2 | F25: ='Refer Para 27'!F40 -> 30 | G25: ='Refer Para 27'!F41 -> 0 | H25: ='Refer Para 27'!F42 -> 0 | I25: ='Refer Para 27'!F43 -> 1 | J25: ='Refer Para 27'!F44 -> 0 | K25: =SUM(C25:J25) -> 323 | L25: 0 | M25: ='Refer Para 27'!F45 -> 1 | N25: =K25+M25-L25 -> 324 | O25: 0
B26: 19 | C26: ='Refer Para 27'!G37 -> 234 | D26: ='Refer Para 27'!G38 -> 196 | E26: ='Refer Para 27'!G39 -> 2 | F26: ='Refer Para 27'!G40 -> 174 | G26: ='Refer Para 27'!G41 -> 0 | H26: ='Refer Para 27'!G42 -> 5 | I26: ='Refer Para 27'!G43 -> 2 | J26: ='Refer Para 27'!G44 -> 1 | K26: =SUM(C26:J26) -> 614 | L26: 0 | M26: ='Refer Para 27'!G45 -> 3 | N26: =K26+M26-L26 -> 617 | O26: 0
B27: 20 | C27: ='Refer Para 27'!H37 -> 113 | D27: ='Refer Para 27'!H38 -> 167 | E27: ='Refer Para 27'!H39 -> 0 | F27: ='Refer Para 27'!H40 -> 281 | G27: ='Refer Para 27'!H41 -> 3 | H27: ='Refer Para 27'!H42 -> 5 | I27: ='Refer Para 27'!H43 -> 1 | J27: ='Refer Para 27'!H44 -> 4 | K27: =SUM(C27:J27) -> 574 | L27: 0 | M27: ='Refer Para 27'!H45 -> 0 | N27: =K27+M27-L27 -> 574 | O27: 0
B28: 21 | C28: ='Refer Para 27'!I37 -> 126 | D28: ='Refer Para 27'!I38 -> 188 | E28: ='Refer Para 27'!I39 -> 3 | F28: ='Refer Para 27'!I40 -> 206 | G28: ='Refer Para 27'!I41 -> 1 | H28: ='Refer Para 27'!I42 -> 0 | I28: ='Refer Para 27'!I43 -> 1 | J28: ='Refer Para 27'!I44 -> 1 | K28: =SUM(C28:J28) -> 526 | L28: 0 | M28: ='Refer Para 27'!I45 -> 1 | N28: =K28+M28-L28 -> 527 | O28: 0
B29: 22 | C29: ='Refer Para 27'!J37 -> 63 | D29: ='Refer Para 27'!J38 -> 321 | E29: ='Refer Para 27'!J39 -> 6 | F29: ='Refer Para 27'!J40 -> 215 | G29: ='Refer Para 27'!J41 -> 2 | H29: ='Refer Para 27'!J42 -> 5 | I29: ='Refer Para 27'!J43 -> 4 | J29: ='Refer Para 27'!J44 -> 1 | K29: =SUM(C29:J29) -> 617 | L29: 0 | M29: ='Refer Para 27'!J45 -> 3 | N29: =K29+M29-L29 -> 620 | O29: 0
B30: 23 | C30: ='Refer Para 27'!K37 -> 23 | D30: ='Refer Para 27'!K38 -> 392 | E30: ='Refer Para 27'!K39 -> 6 | F30: ='Refer Para 27'!K40 -> 92 | G30: ='Refer Para 27'!K41 -> 0 | H30: ='Refer Para 27'!K42 -> 2 | I30: ='Refer Para 27'!K43 -> 2 | J30: ='Refer Para 27'!K44 -> 0 | K30: =SUM(C30:J30) -> 517 | L30: 0 | M30: ='Refer Para 27'!K45 -> 2 | N30: =K30+M30-L30 -> 519 | O30: 0
B31: 24 | C31: ='Refer Para 27'!L37 -> 26 | D31: ='Refer Para 27'!L38 -> 398 | E31: ='Refer Para 27'!L39 -> 6 | F31: ='Refer Para 27'!L40 -> 9 | G31: ='Refer Para 27'!L41 -> 2 | H31: ='Refer Para 27'!L42 -> 4 | I31: ='Refer Para 27'!L43 -> 8 | J31: ='Refer Para 27'!L44 -> 1 | K31: =SUM(C31:J31) -> 454 | L31: 0 | M31: ='Refer Para 27'!L45 -> 1 | N31: =K31+M31-L31 -> 455 | O31: 0
B32: 25 | C32: ='Refer Para 27'!M37 -> 195 | D32: ='Refer Para 27'!M38 -> 443 | E32: ='Refer Para 27'!M39 -> 4 | F32: ='Refer Para 27'!M40 -> 4 | G32: ='Refer Para 27'!M41 -> 0 | H32: ='Refer Para 27'!M42 -> 1 | I32: ='Refer Para 27'!M43 -> 0 | J32: ='Refer Para 27'!M44 -> 0 | K32: =SUM(C32:J32) -> 647 | L32: 0 | M32: ='Refer Para 27'!M45 -> 3 | N32: =K32+M32-L32 -> 650 | O32: 0
B33: 26 | C33: ='Refer Para 27'!N37 -> 313 | D33: ='Refer Para 27'!N38 -> 367 | E33: ='Refer Para 27'!N39 -> 1 | F33: ='Refer Para 27'!N40 -> 7 | G33: ='Refer Para 27'!N41 -> 1 | H33: ='Refer Para 27'!N42 -> 0 | I33: ='Refer Para 27'!N43 -> 3 | J33: ='Refer Para 27'!N44 -> 1 | K33: =SUM(C33:J33) -> 693 | L33: 0 | M33: ='Refer Para 27'!N45 -> 3 | N33: =K33+M33-L33 -> 696 | O33: 0
B34: 27 | C34: ='Refer Para 27'!O37 -> 157 | D34: ='Refer Para 27'!O38 -> 379 | E34: ='Refer Para 27'!O39 -> 14 | F34: ='Refer Para 27'!O40 -> 14 | G34: ='Refer Para 27'!O41 -> 6 | H34: ='Refer Para 27'!O42 -> 2 | I34: ='Refer Para 27'!O43 -> 3 | J34: ='Refer Para 27'!O44 -> 2 | K34: =SUM(C34:J34) -> 577 | L34: 0 | M34: ='Refer Para 27'!O45 -> 4 | N34: =K34+M34-L34 -> 581 | O34: 0
B35: 28 | C35: ='Refer Para 27'!P37 -> 78 | D35: ='Refer Para 27'!P38 -> 199 | E35: ='Refer Para 27'!P39 -> 7 | F35: ='Refer Para 27'!P40 -> 371 | G35: ='Refer Para 27'!P41 -> 10 | H35: ='Refer Para 27'!P42 -> 9 | I35: ='Refer Para 27'!P43 -> 5 | J35: ='Refer Para 27'!P44 -> 1 | K35: =SUM(C35:J35) -> 680 | L35: 0 | M35: ='Refer Para 27'!P45 -> 3 | N35: =K35+M35-L35 -> 683 | O35: 0
B36: 29 | C36: ='Refer Para 27'!C66 -> 134 | D36: ='Refer Para 27'!C67 -> 447 | E36: ='Refer Para 27'!C68 -> 3 | F36: ='Refer Para 27'!C69 -> 87 | G36: ='Refer Para 27'!C70 -> 0 | H36: ='Refer Para 27'!C71 -> 1 | I36: ='Refer Para 27'!C72 -> 6 | J36: ='Refer Para 27'!C73 -> 1 | K36: =SUM(C36:J36) -> 679 | L36: 0 | M36: ='Refer Para 27'!C74 -> 5 | N36: =K36+M36-L36 -> 684 | O36: 0
B37: 30 | C37: ='Refer Para 27'!D66 -> 43 | D37: ='Refer Para 27'!D67 -> 327 | E37: ='Refer Para 27'!D68 -> 1 | F37: ='Refer Para 27'!D69 -> 31 | G37: ='Refer Para 27'!D70 -> 0 | H37: ='Refer Para 27'!D71 -> 1 | I37: ='Refer Para 27'!D72 -> 3 | J37: ='Refer Para 27'!D73 -> 0 | K37: =SUM(C37:J37) -> 406 | L37: 0 | M37: ='Refer Para 27'!D74 -> 0 | N37: =K37+M37-L37 -> 406 | O37: 0
B38: 31 | C38: ='Refer Para 27'!E66 -> 66 | D38: ='Refer Para 27'!E67 -> 369 | E38: ='Refer Para 27'!E68 -> 4 | F38: ='Refer Para 27'!E69 -> 2 | G38: ='Refer Para 27'!E70 -> 1 | H38: ='Refer Para 27'!E71 -> 0 | I38: ='Refer Para 27'!E72 -> 0 | J38: ='Refer Para 27'!E73 -> 0 | K38: =SUM(C38:J38) -> 442 | L38: 0 | M38: ='Refer Para 27'!E74 -> 0 | N38: =K38+M38-L38 -> 442 | O38: 0
B39: 32 | C39: ='Refer Para 27'!F66 -> 348 | D39: ='Refer Para 27'!F67 -> 188 | E39: ='Refer Para 27'!F68 -> 2 | F39: ='Refer Para 27'!F69 -> 12 | G39: ='Refer Para 27'!F70 -> 0 | H39: ='Refer Para 27'!F71 -> 0 | I39: ='Refer Para 27'!F72 -> 0 | J39: ='Refer Para 27'!F73 -> 0 | K39: =SUM(C39:J39) -> 550 | L39: 0 | M39: ='Refer Para 27'!F74 -> 0 | N39: =K39+M39-L39 -> 550 | O39: 0
B40: 33 | C40: ='Refer Para 27'!G66 -> 226 | D40: ='Refer Para 27'!G67 -> 171 | E40: ='Refer Para 27'!G68 -> 0 | F40: ='Refer Para 27'!G69 -> 0 | G40: ='Refer Para 27'!G70 -> 1 | H40: ='Refer Para 27'!G71 -> 1 | I40: ='Refer Para 27'!G72 -> 0 | J40: ='Refer Para 27'!G73 -> 1 | K40: =SUM(C40:J40) -> 400 | L40: 0 | M40: ='Refer Para 27'!G74 -> 0 | N40: =K40+M40-L40 -> 400 | O40: 0
...

Sheet 66 SYANA RESULT BUTH WISE-2022
B1: fo/kku lHkk lkekU; fuokZpu&2022
B2: vfUre ifj.kke erns; LFky okj
B3: 66&L;kuk fo/kku lHkk fuokZpu {ks=
B4: fo/kku lHkk fuokZpu {ks= esa dqy ernkrkvksa dh la[;k& 385012
B5: iksfyax LVs'ku dh dze la[;k | C5: dUVªksy ;wfuV dh la[;k | D5: erns; LFky ij Mkys x;s dqy erksa dh la[;k | E5: fuEufyf[kr vH;fFkZ;ksa ds i{k esa fn;s x;s fof/k ekU; erksa dh la[;k | M5: dqy fof/kekU; er | N5: ¼Rejected½ izfr{ksfir erksa dh la[;k | O5: buesa ls dksbZ ugh ¼uksVk½ | P5: ;ksx | Q5: ¼VsaMj½ fufonRr erksa dh la[;k
E6: fnyuokt [kku | F6: nsosUnz flag yks/kh | G6: dq0 iwue | H6: lquhy dqekj | I6: lrohj flag | J6: Kkus'k dqekj pkSgku | K6: fnus'k | L6: laxhrk
B7: 1 | C7: ECUEC57730 | D7: 748 | E7: ='66 SYANA PRAROOP-20'!C8 -> 258 | F7: ='66 SYANA PRAROOP-20'!D8 -> 438 | G7: ='66 SYANA PRAROOP-20'!E8 -> 8 | H7: ='66 SYANA PRAROOP-20'!F8 -> 35 | I7: ='66 SYANA PRAROOP-20'!G8 -> 1 | J7: ='66 SYANA PRAROOP-20'!H8 -> 2 | K7: ='66 SYANA PRAROOP-20'!I8 -> 2 | L7: ='66 SYANA PRAROOP-20'!J8 -> 2 | M7: =SUM(E7:L7) -> 746 | N7: 0 | O7: ='66 SYANA PRAROOP-20'!M8 -> 2 | P7: =M7+O7-N7 -> 748 | Q7: 0
B8: 2 | C8: ECUEC60998 | D8: 663 | E8: ='66 SYANA PRAROOP-20'!C9 -> 151 | F8: ='66 SYANA PRAROOP-20'!D9 -> 197 | G8: ='66 SYANA PRAROOP-20'!E9 -> 10 | H8: ='66 SYANA PRAROOP-20'!F9 -> 293 | I8: ='66 SYANA PRAROOP-20'!G9 -> 2 | J8: ='66 SYANA PRAROOP-20'!H9 -> 3 | K8: ='66 SYANA PRAROOP-20'!I9 -> 6 | L8: ='66 SYANA PRAROOP-20'!J9 -> 0 | M8: =SUM(E8:L8) -> 662 | N8: 0 | O8: ='66 SYANA PRAROOP-20'!M9 -> 1 | P8: =M8+O8-N8 -> 663 | Q8: 0
B9: 3 | C9: ECUEC54512 | D9: 724 | E9: ='66 SYANA PRAROOP-20'!C10 -> 45 | F9: ='66 SYANA PRAROOP-20'!D10 -> 527 | G9: ='66 SYANA PRAROOP-20'!E10 -> 16 | H9: ='66 SYANA PRAROOP-20'!F10 -> 95 | I9: ='66 SYANA PRAROOP-20'!G10 -> 5 | J9: ='66 SYANA PRAROOP-20'!H10 -> 6 | K9: ='66 SYANA PRAROOP-20'!I10 -> 12 | L9: ='66 SYANA PRAROOP-20'!J10 -> 11 | M9: =SUM(E9:L9) -> 717 | N9: 0 | O9: ='66 SYANA PRAROOP-20'!M10 -> 7 | P9: =M9+O9-N9 -> 724 | Q9: 0
B10: 4 | C10: ECUEC54315 | D10: 495 | E10: ='66 SYANA PRAROOP-20'!C11 -> 63 | F10: ='66 SYANA PRAROOP-20'!D11 -> 339 | G10: ='66 SYANA PRAROOP-20'!E11 -> 18 | H10: ='66 SYANA PRAROOP-20'!F11 -> 64 | I10: ='66 SYANA PRAROOP-20'!G11 -> 2 | J10: ='66 SYANA PRAROOP-20'!H11 -> 1 | K10: ='66 SYANA PRAROOP-20'!I11 -> 0 | L10: ='66 SYANA PRAROOP-20'!J11 -> 6 | M10: =SUM(E10:L10) -> 493 | N10: 0 | O10: ='66 SYANA PRAROOP-20'!M11 -> 2 | P10: =M10+O10-N10 -> 495 | Q10: 0
B11: 5 | C11: ECUEC54992 | D11: 497 | E11: ='66 SYANA PRAROOP-20'!C12 -> 67 | F11: ='66 SYANA PRAROOP-20'!D12 -> 305 | G11: ='66 SYANA PRAROOP-20'!E12 -> 28 | H11: ='66 SYANA PRAROOP-20'!F12 -> 75 | I11: ='66 SYANA PRAROOP-20'!G12 -> 0 | J11: ='66 SYANA PRAROOP-20'!H12 -> 2 | K11: ='66 SYANA PRAROOP-20'!I12 -> 5 | L11: ='66 SYANA PRAROOP-20'!J12 -> 9 | M11: =SUM(E11:L11) -> 491 | N11: 0 | O11: ='66 SYANA PRAROOP-20'!M12 -> 6 | P11: =M11+O11-N11 -> 497 | Q11: 0
B12: 6 | C12: ECUED23745 | D12: 750 | E12: ='66 SYANA PRAROOP-20'!C13 -> 52 | F12: ='66 SYANA PRAROOP-20'!D13 -> 666 | G12: ='66 SYANA PRAROOP-20'!E13 -> 9 | H12: ='66 SYANA PRAROOP-20'!F13 -> 1 | I12: ='66 SYANA PRAROOP-20'!G13 -> 1 | J12: ='66 SYANA PRAROOP-20'!H13 -> 0 | K12: ='66 SYANA PRAROOP-20'!I13 -> 4 | L12: ='66 SYANA PRAROOP-20'!J13 -> 7 | M12: =SUM(E12:L12) -> 740 | N12: 0 | O12: ='66 SYANA PRAROOP-20'!M13 -> 10 | P12: =M12+O12-N12 -> 750 | Q12: 0
B13: 7 | C13: ECUEC64437 | D13: 610 | E13: ='66 SYANA PRAROOP-20'!C14 -> 28 | F13: ='66 SYANA PRAROOP-20'!D14 -> 557 | G13: ='66 SYANA PRAROOP-20'!E14 -> 10 | H13: ='66 SYANA PRAROOP-20'!F14 -> 7 | I13: ='66 SYANA PRAROOP-20'!G14 -> 1 | J13: ='66 SYANA PRAROOP-20'!H14 -> 2 | K13: ='66 SYANA PRAROOP-20'!I14 -> 1 | L13: ='66 SYANA PRAROOP-20'!J14 -> 2 | M13: =SUM(E13:L13) -> 608 | N13: 0 | O13: ='66 SYANA PRAROOP-20'!M14 -> 2 | P13: =M13+O13-N13 -> 610 | Q13: 0
B14: 8 | C14: ECUEC57629 | D14: 796 | E14: ='66 SYANA PRAROOP-20'!C15 -> 160 | F14: ='66 SYANA PRAROOP-20'!D15 -> 613 | G14: ='66 SYANA PRAROOP-20'!E15 -> 13 | H14: ='66 SYANA PRAROOP-20'!F15 -> 3 | I14: ='66 SYANA PRAROOP-20'!G15 -> 1 | J14: ='66 SYANA PRAROOP-20'!H15 -> 2 | K14: ='66 SYANA PRAROOP-20'!I15 -> 1 | L14: ='66 SYANA PRAROOP-20'!J15 -> 2 | M14: =SUM(E14:L14) -> 795 | N14: 0 | O14: ='66 SYANA PRAROOP-20'!M15 -> 1 | P14: =M14+O14-N14 -> 796 | Q14: 0
B15: 9 | C15: ECUED21307 | D15: 573 | E15: ='66 SYANA PRAROOP-20'!C16 -> 161 | F15: ='66 SYANA PRAROOP-20'!D16 -> 322 | G15: ='66 SYANA PRAROOP-20'!E16 -> 1 | H15: ='66 SYANA PRAROOP-20'!F16 -> 78 | I15: ='66 SYANA PRAROOP-20'!G16 -> 2 | J15: ='66 SYANA PRAROOP-20'!H16 -> 2 | K15: ='66 SYANA PRAROOP-20'!I16 -> 1 | L15: ='66 SYANA PRAROOP-20'!J16 -> 4 | M15: =SUM(E15:L15) -> 571 | N15: 0 | O15: ='66 SYANA PRAROOP-20'!M16 -> 2 | P15: =M15+O15-N15 -> 573 | Q15: 0
B16: 10 | C16: ECUED24248 | D16: 634 | E16: ='66 SYANA PRAROOP-20'!C17 -> 264 | F16: ='66 SYANA PRAROOP-20'!D17 -> 321 | G16: ='66 SYANA PRAROOP-20'!E17 -> 2 | H16: ='66 SYANA PRAROOP-20'!F17 -> 42 | I16: ='66 SYANA PRAROOP-20'!G17 -> 0 | J16: ='66 SYANA PRAROOP-20'!H17 -> 3 | K16: ='66 SYANA PRAROOP-20'!I17 -> 0 | L16: ='66 SYANA PRAROOP-20'!J17 -> 0 | M16: =SUM(E16:L16) -> 632 | N16: 0 | O16: ='66 SYANA PRAROOP-20'!M17 -> 2 | P16: =M16+O16-N16 -> 634 | Q16: 0
B17: 11 | C17: ECUEC47814 | D17: 564 | E17: ='66 SYANA PRAROOP-20'!C18 -> 200 | F17: ='66 SYANA PRAROOP-20'!D18 -> 344 | G17: ='66 SYANA PRAROOP-20'!E18 -> 13 | H17: ='66 SYANA PRAROOP-20'!F18 -> 4 | I17: ='66 SYANA PRAROOP-20'!G18 -> 1 | J17: ='66 SYANA PRAROOP-20'!H18 -> 1 | K17: ='66 SYANA PRAROOP-20'!I18 -> 0 | L17: ='66 SYANA PRAROOP-20'!J18 -> 0 | M17: =SUM(E17:L17) -> 563 | N17: 0 | O17: ='66 SYANA PRAROOP-20'!M18 -> 1 | P17: =M17+O17-N17 -> 564 | Q17: 0
B18: 12 | C18: ECUEC54095 | D18: 507 | E18: ='66 SYANA PRAROOP-20'!C19 -> 48 | F18: ='66 SYANA PRAROOP-20'!D19 -> 319 | G18: ='66 SYANA PRAROOP-20'!E19 -> 8 | H18: ='66 SYANA PRAROOP-20'!F19 -> 118 | I18: ='66 SYANA PRAROOP-20'!G19 -> 3 | J18: ='66 SYANA PRAROOP-20'!H19 -> 6 | K18: ='66 SYANA PRAROOP-20'!I19 -> 5 | L18: ='66 SYANA PRAROOP-20'!J19 -> 0 | M18: =SUM(E18:L18) -> 507 | N18: 0 | O18: ='66 SYANA PRAROOP-20'!M19 -> 0 | P18: =M18+O18-N18 -> 507 | Q18: 0
... B444: 438 | C444: ECUEC57608 | D444: 231 | E444: ='66 SYANA PRAROOP-20'!C445 -> 103 | F444: ='66 SYANA PRAROOP-20'!D445 -> 120 | G444: ='66 SYANA PRAROOP-20'!E445 -> 1 | H444: ='66 SYANA PRAROOP-20'!F445 -> 3 | I444: ='66 SYANA PRAROOP-20'!G445 -> 0 | J444: ='66 SYANA PRAROOP-20'!H445 -> 2 | K444: ='66 SYANA PRAROOP-20'!I445 -> 0 | L444: ='66 SYANA PRAROOP-20'!J445 -> 2 | M444: =SUM(E444:L444) -> 231 | N444: 0 | O444: ='66 SYANA PRAROOP-20'!M445 -> 0 | P444: =M444+O444-N444 -> 231 | Q444: 0
B445: TOTAL | D445: =SUM(D7:D444) -> 251967 | E445: =SUM(E7:E444) -> 59207 | F445: =SUM(F7:F444) -> 148342 | G445: =SUM(G7:G444) -> 2888 | H445: =SUM(H7:H444) -> 36043 | I445: =SUM(I7:I444) -> 728 | J445: =SUM(J7:J444) -> 1235 | K445: =SUM(K7:K444) -> 1109 | ... Q445: =SUM(Q7:Q444) -> 0
B446: POSTAL BALLOT | D446: 0 | E446: 261 | F446: 783 | G446: 26 | H446: 150 | I446: 10 | J446: 2 | K446: 0 | L446: 2 | M446: =SUM(E446:L446) -> 1234 | N446: 542 | O446: ='66 SYANA PRAROOP-20'!M447 -> 2 | P446: =M446+O446+N446 -> 1778 | Q446: 0
B447: GRAND TOTAL | D447: =D445+D446 -> 251967 | E447: =E445+E446 -> 59468 | F447: =F445+F446 -> 149125 | G447: =G445+G446 -> 2914 | H447: =H445+H446 -> 36193 | I447: =I445+I446 -> 738 | J447: =J445+J446 -> 1237 | K447: =K445+K446 -> 1109 | ... Q447: =Q445+Q446 -> 0
N451: fjVfuZax vkWfQlj
N452: 66-L;kuk

Sheet All Data
A1: No. & Name Assembly Constituency- 66-Syana
A2: UTTAR PRADESH VIDHAN SABHA GENERAL ELECTION 2022
A3: DISTRICT - BULANDSHAHR
A4: Ac. No. | B4: Polling Station | D4: Total No. of Electors | E4: Voters Turnout | I4: No. of voters identified using EPIC | J4: No. of Ten-dered Voters | K4: Dilnawaz Khan | N4: Devendra Singh Lodhi | Q4: Km. Poonam | T4: Sunil Kumar | W4: Satvir Singh | Z4: Gyanesh Kumar Chauhan | AC4: Dinesh | AF4: Snageeta | AI4: Total voters Secured
B5: No. | C5: Name | E5: Male | F5: Female | G5: Other | H5: Total | K5: S.No. | L5: Party Affiliation | M5: Voters Secured | N5: S.No. | O5: Party Affiliation | P5: Voters Secured | Q5: S.No. | R5: Party Affiliation | S5: Voters Secured | T5: S.No. | U5: Party Affiliation | V5: Voters Secured | W5: S.No. | X5: Party Affiliation | Y5: Voters Secured | Z5: S.No. | AA5: Party Affiliation | AB5: Voters Secured | AC5: S.No. | AD5: Party Affiliation | AE5: Voters Secured | AF5: S.No. | AG5: Party Affiliation | AH5: Voters Secured
A6: 1 | B6: 2 | C6: 3 | D6: 4 | E6: 5 | F6: 6 | G6: 7 | H6: 8 | I6: 9 | J6: 10 | K6: 11 | L6: 12 | M6: 13 | N6: 14 | O6: 15 | P6: 16 | Q6: 17 | R6: 18 | S6: 19 | T6: 20 | U6: 21 | V6: 22 | W6: 23 | X6: 24 | Y6: 25 | Z6: 26 | AA6: 27 | AB6: 28 | AC6: 29 | AD6: 30 | AE6: 31 | AF6: 32 | AG6: 33 | AH6: 34 | AI6: 35
A7: 66 | B7: 1 | C7: KUCHESER R R K K INTER COLLEGE ROOM NO- 1 | D7: 1090 | E7: 402 | F7: 346 | G7: 0 | H7: =SUM(E7:G7) -> 748 | I7: 502 | J7: 0 | K7: 1 | L7: Rashtriya Lok Dal | M7: ='66 SYANA PRAROOP-20'!C8 -> 258 | N7: 2 | O7: Bharatiya Janata Party | P7: ='66 SYANA PRAROOP-20'!D8 -> 438 | Q7: 3 | R7: Indian National Congrass | S7: ='66 SYANA PRAROOP-20'!E8 -> 8 | T7: 4 | U7: Bahujan Samaj Party | V7: ='66 SYANA PRAROOP-20'!F8 -> 35 | W7: 5 | X7: Aam Aadmi Party | Y7: ='66 SYANA PRAROOP-20'!G8 -> 1 | Z7: 6 | AA7: Hindustan Uttan Party | AB7: ='66 SYANA PRAROOP-20'!H8 -> 2 | AC7: 7 | AD7: Independent | AE7: ='66 SYANA PRAROOP-20'!I8 -> 2 | AF7: 8 | AG7: Independent | AH7: ='66 SYANA PRAROOP-20'!J8 -> 2 | AI7: =M7+P7+S7+V7+Y7+AB7+AE7+AH7 -> 746 | AJ7: =AI7-H7 -> -2
A8: 66 | B8: 2 | C8: KUCHESER R R K K INTER COLLEGE ROOM NO- 2 | D8: 1119 | E8: 373 | F8: 290 | G8: 0 | H8: =SUM(E8:G8) -> 663 | I8: 103 | J8: 0 | M8: ='66 SYANA PRAROOP-20'!C9 -> 151 | P8: ='66 SYANA PRAROOP-20'!D9 -> 197 | S8: ='66 SYANA PRAROOP-20'!E9 -> 10 | V8: ='66 SYANA PRAROOP-20'!F9 -> 293 | Y8: ='66 SYANA PRAROOP-20'!G9 -> 2 | AB8: ='66 SYANA PRAROOP-20'!H9 -> 3 | AE8: ='66 SYANA PRAROOP-20'!I9 -> 6 | AH8: ='66 SYANA PRAROOP-20'!J9 -> 0 | AI8: =M8+P8+S8+V8+Y8+AB8+AE8+AH8 -> 662 | AJ8: =AI8-H8 -> -1
A9: 66 | B9: 3 | C9: KUCHESER R R K K INTER COLLEGE ROOM NO- 3 | D9: 1183 | E9: 380 | F9: 344 | G9: 0 | H9: =SUM(E9:G9) -> 724 | I9: 92 | J9: 0 | M9: ='66 SYANA PRAROOP-20'!C10 -> 45 | P9: ='66 SYANA PRAROOP-20'!D10 -> 527 | S9: ='66 SYANA PRAROOP-20'!E10 -> 16 | V9: ='66 SYANA PRAROOP-20'!F10 -> 95 | Y9: ='66 SYANA PRAROOP-20'!G10 -> 5 | AB9: ='66 SYANA PRAROOP-20'!H10 -> 6 | AE9: ='66 SYANA PRAROOP-20'!I10 -> 12 | AH9: ='66 SYANA PRAROOP-20'!J10 -> 11 | AI9: =M9+P9+S9+V9+Y9+AB9+AE9+AH9 -> 717 | AJ9: =AI9-H9 -> -7
A10: 66 | B10: 4 | C10: KUCHESER R R K K INTER COLLEGE ROOM NO- 4 | D10: 703 | E10: 259 | F10: 236 | G10: 0 | H10: =SUM(E10:G10) -> 495 | I10: 56 | J10: 0 | M10: ='66 SYANA PRAROOP-20'!C11 -> 63 | P10: ='66 SYANA PRAROOP-20'!D11 -> 339 | S10: ='66 SYANA PRAROOP-20'!E11 -> 18 | V10: ='66 SYANA PRAROOP-20'!F11 -> 64 | Y10: ='66 SYANA PRAROOP-20'!G11 -> 2 | AB10: ='66 SYANA PRAROOP-20'!H11 -> 1 | AE10: ='66 SYANA PRAROOP-20'!I11 -> 0 | AH10: ='66 SYANA PRAROOP-20'!J11 -> 6 | AI10: =M10+P10+S10+V10+Y10+AB10+AE10+AH10 -> 493 | AJ10: =AI10-H10 -> -2
A11: 66 | B11: 5 | C11: KUCHESER R R K K INTER COLLEGE ROOM NO- 5 | D11: 714 | E11: 266 | F11: 231 | G11: 0 | H11: =SUM(E11:G11) -> 497 | I11: 301 | J11: 0 | M11: ='66 SYANA PRAROOP-20'!C12 -> 67 | P11: ='66 SYANA PRAROOP-20'!D12 -> 305 | S11: ='66 SYANA PRAROOP-20'!E12 -> 28 | V11: ='66 SYANA PRAROOP-20'!F12 -> 75 | Y11: ='66 SYANA PRAROOP-20'!G12 -> 0 | AB11: ='66 SYANA PRAROOP-20'!H12 -> 2 | AE11: ='66 SYANA PRAROOP-20'!I12 -> 5 | AH11: ='66 SYANA PRAROOP-20'!J12 -> 9 | AI11: =M11+P11+S11+V11+Y11+AB11+AE11+AH11 -> 491 | AJ11: =AI11-H11 -> -6
A12: 66 | B12: 6 | C12: LUDHPURA PRIMARY SCHOOL ROOM NO-1 | D12: 984 | E12: 389 | F12: 361 | G12: 0 | H12: =SUM(E12:G12) -> 750 | I12: 289 | J12: 0 | M12: ='66 SYANA PRAROOP-20'!C13 -> 52 | P12: ='66 SYANA PRAROOP-20'!D13 -> 666 | S12: ='66 SYANA PRAROOP-20'!E13 -> 9 | V12: ='66 SYANA PRAROOP-20'!F13 -> 1 | Y12: ='66 SYANA PRAROOP-20'!G13 -> 1 | AB12: ='66 SYANA PRAROOP-20'!H13 -> 0 | AE12: ='66 SYANA PRAROOP-20'!I13 -> 4 | AH12: ='66 SYANA PRAROOP-20'!J13 -> 7 | AI12: =M12+P12+S12+V12+Y12+AB12+AE12+AH12 -> 740 | AJ12: =AI12-H12 -> -10
A13: 66 | B13: 7 | C13: LUDHPURA PRIMARY SCHOOL ROOM NO-2 | D13: 757 | E13: 297 | F13: 313 | G13: 0 | H13: =SUM(E13:G13) -> 610 | I13: 197 | J13: 0 | M13: ='66 SYANA PRAROOP-20'!C14 -> 28 | P13: ='66 SYANA PRAROOP-20'!D14 -> 557 | S13: ='66 SYANA PRAROOP-20'!E14 -> 10 | V13: ='66 SYANA PRAROOP-20'!F14 -> 7 | Y13: ='66 SYANA PRAROOP-20'!G14 -> 1 | AB13: ='66 SYANA PRAROOP-20'!H14 -> 2 | AE13: ='66 SYANA PRAROOP-20'!I14 -> 1 | AH13: ='66 SYANA PRAROOP-20'!J14 -> 2 | AI13: =M13+P13+S13+V13+Y13+AB13+AE13+AH13 -> 608 | AJ13: =AI13-H13 -> -2
A14: 66 | B14: 8 | C14: KUCHESAR PRIMARY SCHOOL | D14: 1167 | E14: 434 | F14: 362 | G14: 0 | H14: =SUM(E14:G14) -> 796 | I14: 88 | J14: 0 | M14: ='66 SYANA PRAROOP-20'!C15 -> 160 | P14: ='66 SYANA PRAROOP-20'!D15 -> 613 | S14: ='66 SYANA PRAROOP-20'!E15 -> 13 | V14: ='66 SYANA PRAROOP-20'!F15 -> 3 | Y14: ='66 SYANA PRAROOP-20'!G15 -> 1 | AB14: ='66 SYANA PRAROOP-20'!H15 -> 2 | AE14: ='66 SYANA PRAROOP-20'!I15 -> 1 | AH14: ='66 SYANA PRAROOP-20'!J15 -> 2 | AI14: =M14+P14+S14+V14+Y14+AB14+AE14+AH14 -> 795 | AJ14: =AI14-H14 -> -1
A15: 66 | B15: 9 | C15: SALABAD DHUMERA PRIMARY SCHOOL ROOM NO-1 | D15: 869 | E15: 302 | F15: 271 | G15: 0 | H15: =SUM(E15:G15) -> 573 | I15: 402 | J15: 0 | M15: ='66 SYANA PRAROOP-20'!C16 -> 161 | P15: ='66 SYANA PRAROOP-20'!D16 -> 322 | S15: ='66 SYANA PRAROOP-20'!E16 -> 1 | V15: ='66 SYANA PRAROOP-20'!F16 -> 78 | Y15: ='66 SYANA PRAROOP-20'!G16 -> 2 | AB15: ='66 SYANA PRAROOP-20'!H16 -> 2 | AE15: ='66 SYANA PRAROOP-20'!I16 -> 1 | AH15: ='66 SYANA PRAROOP-20'!J16 -> 4 | AI15: =M15+P15+S15+V15+Y15+AB15+AE15+AH15 -> 571 | AJ15: =AI15-H15 -> -2
A16: 66 | B16: 10 | C16: SALABAD DHUMERA PRIMARY SCHOOL ROOM NO-2 | D16: 956 | E16: 335 | F16: 299 | G16: 0 | H16: =SUM(E16:G16) -> 634 | I16: 455 | J16: 0 | M16: ='66 SYANA PRAROOP-20'!C17 -> 264 | P16: ='66 SYANA PRAROOP-20'!D17 -> 321 | S16: ='66 SYANA PRAROOP-20'!E17 -> 2 | V16: ='66 SYANA PRAROOP-20'!F17 -> 42 | Y16: ='66 SYANA PRAROOP-20'!G17 -> 0 | AB16: ='66 SYANA PRAROOP-20'!H17 -> 3 | AE16: ='66 SYANA PRAROOP-20'!I17 -> 0 | AH16: ='66 SYANA PRAROOP-20'!J17 -> 0 | AI16: =M16+P16+S16+V16+Y16+AB16+AE16+AH16 -> 632 | AJ16: =AI16-H16 -> -2
A17: 66 | B17: 11 | C17: TIVARA PRIMARY SCHOOL | D17: 879 | E17: 300 | F17: 264 | G17: 0 | H17: =SUM(E17:G17) -> 564 | I17: 400 | J17: 0 | M17: ='66 SYANA PRAROOP-20'!C18 -> 200 | P17: ='66 SYANA PRAROOP-20'!D18 -> 344 | S17: ='66 SYANA PRAROOP-20'!E18 -> 13 | V17: ='66 SYANA PRAROOP-20'!F18 -> 4 | Y17: ='66 SYANA PRAROOP-20'!G18 -> 1 | AB17: ='66 SYANA PRAROOP-20'!H18 -> 1 | AE17: ='66 SYANA PRAROOP-20'!I18 -> 0 | AH17: ='66 SYANA PRAROOP-20'!J18 -> 0 | AI17: =M17+P17+S17+V17+Y17+AB17+AE17+AH17 -> 563 | AJ17: =AI17-H17 -> -1
A18: 66 | B18: 12 | C18: BARKATPUR PRIMARY SCHOOL | D18: 867 | E18: 288 | F18: 219 | G18: 0 | H18: =SUM(E18:G18) -> 507 | I18: 50 | J18: 0 | M18: ='66 SYANA PRAROOP-20'!C19 -> 48 | P18: ='66 SYANA PRAROOP-20'!D19 -> 319 | S18: ='66 SYANA PRAROOP-20'!E19 -> 8 | V18: ='66 SYANA PRAROOP-20'!F19 -> 118 | Y18: ='66 SYANA PRAROOP-20'!G19 -> 3 | AB18: ='66 SYANA PRAROOP-20'!H19 -> 6 | AE18: ='66 SYANA PRAROOP-20'!I19 -> 5 | AH18: ='66 SYANA PRAROOP-20'!J19 -> 0 | AI18: =M18+P18+S18+V18+Y18+AB18+AE18+AH18 -> 507 | AJ18: =AI18-H18 -> 0
A19: 66 | B19: 13 | C19: DHAKAULI PRIMARY SCHOOL ROOM NO-1 | D19: 720 | E19: 240 | F19: 185 | G19: 0 | H19: =SUM(E19:G19) -> 425 | I19: 250 | J19: 0 | M19: ='66 SYANA PRAROOP-20'!C20 -> 213 | P19: ='66 SYANA PRAROOP-20'!D20 -> 190 | S19: ='66 SYANA PRAROOP-20'!E20 -> 1 | V19: ='66 SYANA PRAROOP-20'!F20 -> 12 | Y19: ='66 SYANA PRAROOP-20'!G20 -> 0 | AB19: ='66 SYANA PRAROOP-20'!H20 -> 0 | AE19: ='66 SYANA PRAROOP-20'!I20 -> 2 | AH19: ='66 SYANA PRAROOP-20'!J20 -> 1 | AI19: =M19+P19+S19+V19+Y19+AB19+AE19+AH19 -> 419 | AJ19: =AI19-H19 -> -6
... A184: 66 | B184: 178 | C184: UPPER PRIMARY SCHOOL BHAGWANPUR MAJRA RAVANI KATIRI ROOM NO.-1 | D184: 646 | E184: 260 | F184: 216 | G184: 0 | H184: =SUM(E184:G184) -> 476 | I184: 360 | J184: 0 | M184: ='66 SYANA PRAROOP-20'!C185 -> 77 | P184: ='66 SYANA PRAROOP-20'!D185 -> 356 | S184: ='66 SYANA PRAROOP-20'!E185 -> 2 | V184: ='66 SYANA PRAROOP-20'!F185 -> 32 | Y184: ='66 SYANA PRAROOP-20'!G185 -> 0 | AB184: ='66 SYANA PRAROOP-20'!H185 -> 3 | AE184: ='66 SYANA PRAROOP-20'!I185 -> 1 | AH184: ='66 SYANA PRAROOP-20'!J185 -> 2 | AI184: =M184+P184+S184+V184+Y184+AB184+AE184+AH184 -> 473 | AJ184: =AI184-H184 -> -3
A185: 66 | B185: 179 | C185: UPPER PRIMARY SCHOOL BHAGWANPUR MAJRA RAVANI KATIRI ROOM NO.-2 | D185: 679 | E185: 219 | F185: 190 | H185: =SUM(E185:G185) -> 409 | I185: 44 | J185: 0 | M185: ='66 SYANA PRAROOP-20'!C186 -> 178 | P185: ='66 SYANA PRAROOP-20'!D186 -> 84 | S185: ='66 SYANA PRAROOP-20'!E186 -> 3 | V185: ='66 SYANA PRAROOP-20'!F186 -> 123 | Y185: ='66 SYANA PRAROOP-20'!G186 -> 2 | AB185: ='66 SYANA PRAROOP-20'!H186 -> 10 | AE185: ='66 SYANA PRAROOP-20'!I186 -> 3 | AH185: ='66 SYANA PRAROOP-20'!J186 -> 4 | AI185: =M185+P185+S185+V185+Y185+AB185+AE185+AH185 -> 407 | AJ185: =AI185-H185 -> -2
A186: 66 | B186: 180 | C186: MAHIUDDINPUR BUKLANA PRIMARY SCHOOL ROOM NO.-1 | D186: 833 | E186: 323 | F186: 276 | G186: 0 | H186: =SUM(E186:G186) -> 599 | I186: 423 | J186: 0 | M186: ='66 SYANA PRAROOP-20'!C187 -> 21 | P186: ='66 SYANA PRAROOP-20'!D187 -> 324 | S186: ='66 SYANA PRAROOP-20'!E187 -> 9 | V186: ='66 SYANA PRAROOP-20'!F187 -> 229 | Y186: ='66 SYANA PRAROOP-20'!G187 -> 2 | AB186: ='66 SYANA PRAROOP-20'!H187 -> 10 | AE186: ='66 SYANA PRAROOP-20'!I187 -> 0 | AH186: ='66 SYANA PRAROOP-20'!J187 -> 2 | AI186: =M186+P186+S186+V186+Y186+AB186+AE186+AH186 -> 597 | AJ186: =AI186-H186 -> -2
A187: 66 | B187: 181 | C187: MAHIUDDINPUR BUKLANA PRIMARY SCHOOL ROOM NO.-2 | D187: 949 | E187: 329 | F187: 339 | G187: 0 | H187: =SUM(E187:G187) -> 668 | I187: 76 | J187: 0 | M187: ='66 SYANA PRAROOP-20'!C188 -> 13 | P187: ='66 SYANA PRAROOP-20'!D188 -> 591 | S187: ='66 SYANA PRAROOP-20'!E188 -> 9 | V187: ='66 SYANA PRAROOP-20'!F188 -> 34 | Y187: ='66 SYANA PRAROOP-20'!G188 -> 1 | AB187: ='66 SYANA PRAROOP-20'!H188 -> 13 | AE187: ='66 SYANA PRAROOP-20'!I188 -> 0 | AH187: ='66 SYANA PRAROOP-20'!J188 -> 4 | AI187: =M187+P187+S187+V187+Y187+AB187+AE187+AH187 -> 665 | AJ187: =AI187-H187 -> -3
A188: 66 | B188: 182 | C188: MAHIUDDINPUR BUKLANA PRIMARY SCHOOL ROOM NO.-3 | D188: 819 | E188: 261 | F188: 241 | G188: 0 | H188: =SUM(E188:G188) -> 502 | I188: 61 | J188: 0 | M188: ='66 SYANA PRAROOP-20'!C189 -> 248 | P188: ='66 SYANA PRAROOP-20'!D189 -> 241 | S188: ='66 SYANA PRAROOP-20'!E189 -> 1 | V188: ='66 SYANA PRAROOP-20'!F189 -> 3 | Y188: ='66 SYANA PRAROOP-20'!G189 -> 0 | AB188: ='66 SYANA PRAROOP-20'!H189 -> 4 | AE188: ='66 SYANA PRAROOP-20'!I189 -> 0 | AH188: ='66 SYANA PRAROOP-20'!J189 -> 1 | AI188: =M188+P188+S188+V188+Y188+AB188+AE188+AH188 -> 498 | AJ188: =AI188-H188 -> -4
A189: 66 | B189: 183 | C189: MAHIUDDINPUR BUKLANA PRIMARY SCHOOL ROOM NO.-4 | D189: 771 | E189: 207 | F189: 197 | G189: 0 | H189: =SUM(E189:G189) -> 404 | I189: 307 | J189: 0 | M189: ='66 SYANA PRAROOP-20'!C190 -> 27 | P189: ='66 SYANA PRAROOP-20'!D190 -> 371 | S189: ='66 SYANA PRAROOP-20'!E190 -> 2 | V189: ='66 SYANA PRAROOP-20'!F190 -> 0 | Y189: ='66 SYANA PRAROOP-20'!G190 -> 0 | AB189: ='66 SYANA PRAROOP-20'!H190 -> 4 | AE189: ='66 SYANA PRAROOP-20'!I190 -> 0 | AH189: ='66 SYANA PRAROOP-20'!J190 -> 0 | AI189: =M189+P189+S189+V189+Y189+AB189+AE189+AH189 -> 404 | AJ189: =AI189-H189 -> 0
A190: 66 | B190: 184 | C190: BARHANA PRIMARY SCHOOL ROOM NO.-1 | D190: 1004 | E190: 328 | F190: 312 | G190: 0 | H190: =SUM(E190:G190) -> 640 | I190: 65 | J190: 0 | M190: ='66 SYANA PRAROOP-20'!C191 -> 68 | P190: ='66 SYANA PRAROOP-20'!D191 -> 432 | S190: ='66 SYANA PRAROOP-20'!E191 -> 3 | V190: ='66 SYANA PRAROOP-20'!F191 -> 125 | Y190: ='66 SYANA PRAROOP-20'!G191 -> 4 | AB190: ='66 SYANA PRAROOP-20'!H191 -> 1 | AE190: ='66 SYANA PRAROOP-20'!I191 -> 3 | AH190: ='66 SYANA PRAROOP-20'!J191 -> 0 | AI190: =M190+P190+S190+V190+Y190+AB190+AE190+AH190 -> 636 | AJ190: =AI190-H190 -> -4
